Internal Server Error: /api/products/
Traceback (most recent call last):
  File "/Users/yxngac/Desktop/Wale_sites/.venv/lib/python3.12/site-packages/django/db/backends/utils.py", line 105, in _execute
    return self.cursor.execute(sql, params)
           ^^^^^^^^^^^^^^^^^^^^^^^^^^^^^^^^
psycopg2.errors.NotNullViolation: null value in column "price" of relation "pharmacy_product" violates not-null constraint
DETAIL:  Failing row contains (1, psychadelics, dyvbgclyihwredsGBVFywrdseushigfbvwrdsieyulGFVBWRDUEYGFVBLWSRUIGF..., null, null, products/Screenshot_2025-09-17_at_1.53.35AM.png, 1, null, 2025-09-21 00:54:04.371098+00, 2025-09-21 00:54:04.371116+00).


The above exception was the direct cause of the following exception:

Traceback (most recent call last):
  File "/Users/yxngac/Desktop/Wale_sites/.venv/lib/python3.12/site-packages/django/core/handlers/exception.py", line 55, in inner
    response = get_response(request)
               ^^^^^^^^^^^^^^^^^^^^^
  File "/Users/yxngac/Desktop/Wale_sites/.venv/lib/python3.12/site-packages/django/core/handlers/base.py", line 197, in _get_response
    response = wrapped_callback(request, *callback_args, **callback_kwargs)
               ^^^^^^^^^^^^^^^^^^^^^^^^^^^^^^^^^^^^^^^^^^^^^^^^^^^^^^^^^^^^
  File "/Users/yxngac/Desktop/Wale_sites/.venv/lib/python3.12/site-packages/django/views/decorators/csrf.py", line 65, in _view_wrapper
    return view_func(request, *args, **kwargs)
           ^^^^^^^^^^^^^^^^^^^^^^^^^^^^^^^^^^^
  File "/Users/yxngac/Desktop/Wale_sites/.venv/lib/python3.12/site-packages/rest_framework/viewsets.py", line 125, in view
    return self.dispatch(request, *args, **kwargs)
           ^^^^^^^^^^^^^^^^^^^^^^^^^^^^^^^^^^^^^^^
  File "/Users/yxngac/Desktop/Wale_sites/.venv/lib/python3.12/site-packages/rest_framework/views.py", line 515, in dispatch
    response = self.handle_exception(exc)
               ^^^^^^^^^^^^^^^^^^^^^^^^^^
  File "/Users/yxngac/Desktop/Wale_sites/.venv/lib/python3.12/site-packages/rest_framework/views.py", line 475, in handle_exception
    self.raise_uncaught_exception(exc)
  File "/Users/yxngac/Desktop/Wale_sites/.venv/lib/python3.12/site-packages/rest_framework/views.py", line 486, in raise_uncaught_exception
    raise exc
  File "/Users/yxngac/Desktop/Wale_sites/.venv/lib/python3.12/site-packages/rest_framework/views.py", line 512, in dispatch
    response = handler(request, *args, **kwargs)
               ^^^^^^^^^^^^^^^^^^^^^^^^^^^^^^^^^
  File "/Users/yxngac/Desktop/Wale_sites/.venv/lib/python3.12/site-packages/rest_framework/mixins.py", line 19, in create
    self.perform_create(serializer)
  File "/Users/yxngac/Desktop/Wale_sites/.venv/lib/python3.12/site-packages/rest_framework/mixins.py", line 24, in perform_create
    serializer.save()
  File "/Users/yxngac/Desktop/Wale_sites/.venv/lib/python3.12/site-packages/rest_framework/serializers.py", line 210, in save
    self.instance = self.create(validated_data)
                    ^^^^^^^^^^^^^^^^^^^^^^^^^^^
  File "/Users/yxngac/Desktop/Wale_sites/.venv/lib/python3.12/site-packages/rest_framework/serializers.py", line 991, in create
    instance = ModelClass._default_manager.create(**validated_data)
               ^^^^^^^^^^^^^^^^^^^^^^^^^^^^^^^^^^^^^^^^^^^^^^^^^^^^
  File "/Users/yxngac/Desktop/Wale_sites/.venv/lib/python3.12/site-packages/django/db/models/manager.py", line 87, in manager_method
    return getattr(self.get_queryset(), name)(*args, **kwargs)
           ^^^^^^^^^^^^^^^^^^^^^^^^^^^^^^^^^^^^^^^^^^^^^^^^^^^
  File "/Users/yxngac/Desktop/Wale_sites/.venv/lib/python3.12/site-packages/django/db/models/query.py", line 663, in create
    obj.save(force_insert=True, using=self.db)
  File "/Users/yxngac/Desktop/Wale_sites/.venv/lib/python3.12/site-packages/django/db/models/base.py", line 902, in save
    self.save_base(
  File "/Users/yxngac/Desktop/Wale_sites/.venv/lib/python3.12/site-packages/django/db/models/base.py", line 1008, in save_base
    updated = self._save_table(
              ^^^^^^^^^^^^^^^^^
  File "/Users/yxngac/Desktop/Wale_sites/.venv/lib/python3.12/site-packages/django/db/models/base.py", line 1169, in _save_table
    results = self._do_insert(
              ^^^^^^^^^^^^^^^^
  File "/Users/yxngac/Desktop/Wale_sites/.venv/lib/python3.12/site-packages/django/db/models/base.py", line 1210, in _do_insert
    return manager._insert(
           ^^^^^^^^^^^^^^^^
  File "/Users/yxngac/Desktop/Wale_sites/.venv/lib/python3.12/site-packages/django/db/models/manager.py", line 87, in manager_method
    return getattr(self.get_queryset(), name)(*args, **kwargs)
           ^^^^^^^^^^^^^^^^^^^^^^^^^^^^^^^^^^^^^^^^^^^^^^^^^^^
  File "/Users/yxngac/Desktop/Wale_sites/.venv/lib/python3.12/site-packages/django/db/models/query.py", line 1868, in _insert
    return query.get_compiler(using=using).execute_sql(returning_fields)
           ^^^^^^^^^^^^^^^^^^^^^^^^^^^^^^^^^^^^^^^^^^^^^^^^^^^^^^^^^^^^^
  File "/Users/yxngac/Desktop/Wale_sites/.venv/lib/python3.12/site-packages/django/db/models/sql/compiler.py", line 1882, in execute_sql
    cursor.execute(sql, params)
  File "/Users/yxngac/Desktop/Wale_sites/.venv/lib/python3.12/site-packages/django/db/backends/utils.py", line 122, in execute
    return super().execute(sql, params)
           ^^^^^^^^^^^^^^^^^^^^^^^^^^^^
  File "/Users/yxngac/Desktop/Wale_sites/.venv/lib/python3.12/site-packages/django/db/backends/utils.py", line 79, in execute
    return self._execute_with_wrappers(
           ^^^^^^^^^^^^^^^^^^^^^^^^^^^^
  File "/Users/yxngac/Desktop/Wale_sites/.venv/lib/python3.12/site-packages/django/db/backends/utils.py", line 92, in _execute_with_wrappers
    return executor(sql, params, many, context)
           ^^^^^^^^^^^^^^^^^^^^^^^^^^^^^^^^^^^^
  File "/Users/yxngac/Desktop/Wale_sites/.venv/lib/python3.12/site-packages/django/db/backends/utils.py", line 100, in _execute
    with self.db.wrap_database_errors:
         ^^^^^^^^^^^^^^^^^^^^^^^^^^^^
  File "/Users/yxngac/Desktop/Wale_sites/.venv/lib/python3.12/site-packages/django/db/utils.py", line 91, in __exit__
    raise dj_exc_value.with_traceback(traceback) from exc_value
  File "/Users/yxngac/Desktop/Wale_sites/.venv/lib/python3.12/site-packages/django/db/backends/utils.py", line 105, in _execute
    return self.cursor.execute(sql, params)
           ^^^^^^^^^^^^^^^^^^^^^^^^^^^^^^^^
django.db.utils.IntegrityError: null value in column "price" of relation "pharmacy_product" violates not-null constraint
DETAIL:  Failing row contains (1, psychadelics, dyvbgclyihwredsGBVFywrdseushigfbvwrdsieyulGFVBWRDUEYGFVBLWSRUIGF..., null, null, products/Screenshot_2025-09-17_at_1.53.35AM.png, 1, null, 2025-09-21 00:54:04.371098+00, 2025-09-21 00:54:04.371116+00).

"POST /api/products/ HTTP/1.1" 500 200744
Internal Server Error: /api/products/
Traceback (most recent call last):
  File "/Users/yxngac/Desktop/Wale_sites/.venv/lib/python3.12/site-packages/django/db/backends/utils.py", line 105, in _execute
    return self.cursor.execute(sql, params)
           ^^^^^^^^^^^^^^^^^^^^^^^^^^^^^^^^
psycopg2.errors.NotNullViolation: null value in column "price" of relation "pharmacy_product" violates not-null constraint
DETAIL:  Failing row contains (2, psychadelics, dyvbgclyihwredsGBVFywrdseushigfbvwrdsieyulGFVBWRDUEYGFVBLWSRUIGF..., null, null, products/Screenshot_2025-09-17_at_1_ee3Fg4l.53.35AM.png, 1, null, 2025-09-21 00:55:03.440121+00, 2025-09-21 00:55:03.440142+00).


The above exception was the direct cause of the following exception:

Traceback (most recent call last):
  File "/Users/yxngac/Desktop/Wale_sites/.venv/lib/python3.12/site-packages/django/core/handlers/exception.py", line 55, in inner
    response = get_response(request)
               ^^^^^^^^^^^^^^^^^^^^^
  File "/Users/yxngac/Desktop/Wale_sites/.venv/lib/python3.12/site-packages/django/core/handlers/base.py", line 197, in _get_response
    response = wrapped_callback(request, *callback_args, **callback_kwargs)
               ^^^^^^^^^^^^^^^^^^^^^^^^^^^^^^^^^^^^^^^^^^^^^^^^^^^^^^^^^^^^
  File "/Users/yxngac/Desktop/Wale_sites/.venv/lib/python3.12/site-packages/django/views/decorators/csrf.py", line 65, in _view_wrapper
    return view_func(request, *args, **kwargs)
           ^^^^^^^^^^^^^^^^^^^^^^^^^^^^^^^^^^^
  File "/Users/yxngac/Desktop/Wale_sites/.venv/lib/python3.12/site-packages/rest_framework/viewsets.py", line 125, in view
    return self.dispatch(request, *args, **kwargs)
           ^^^^^^^^^^^^^^^^^^^^^^^^^^^^^^^^^^^^^^^
  File "/Users/yxngac/Desktop/Wale_sites/.venv/lib/python3.12/site-packages/rest_framework/views.py", line 515, in dispatch
    response = self.handle_exception(exc)
               ^^^^^^^^^^^^^^^^^^^^^^^^^^
  File "/Users/yxngac/Desktop/Wale_sites/.venv/lib/python3.12/site-packages/rest_framework/views.py", line 475, in handle_exception
    self.raise_uncaught_exception(exc)
  File "/Users/yxngac/Desktop/Wale_sites/.venv/lib/python3.12/site-packages/rest_framework/views.py", line 486, in raise_uncaught_exception
    raise exc
  File "/Users/yxngac/Desktop/Wale_sites/.venv/lib/python3.12/site-packages/rest_framework/views.py", line 512, in dispatch
    response = handler(request, *args, **kwargs)
               ^^^^^^^^^^^^^^^^^^^^^^^^^^^^^^^^^
  File "/Users/yxngac/Desktop/Wale_sites/.venv/lib/python3.12/site-packages/rest_framework/mixins.py", line 19, in create
    self.perform_create(serializer)
  File "/Users/yxngac/Desktop/Wale_sites/.venv/lib/python3.12/site-packages/rest_framework/mixins.py", line 24, in perform_create
    serializer.save()
  File "/Users/yxngac/Desktop/Wale_sites/.venv/lib/python3.12/site-packages/rest_framework/serializers.py", line 210, in save
    self.instance = self.create(validated_data)
                    ^^^^^^^^^^^^^^^^^^^^^^^^^^^
  File "/Users/yxngac/Desktop/Wale_sites/.venv/lib/python3.12/site-packages/rest_framework/serializers.py", line 991, in create
    instance = ModelClass._default_manager.create(**validated_data)
               ^^^^^^^^^^^^^^^^^^^^^^^^^^^^^^^^^^^^^^^^^^^^^^^^^^^^
  File "/Users/yxngac/Desktop/Wale_sites/.venv/lib/python3.12/site-packages/django/db/models/manager.py", line 87, in manager_method
    return getattr(self.get_queryset(), name)(*args, **kwargs)
           ^^^^^^^^^^^^^^^^^^^^^^^^^^^^^^^^^^^^^^^^^^^^^^^^^^^
  File "/Users/yxngac/Desktop/Wale_sites/.venv/lib/python3.12/site-packages/django/db/models/query.py", line 663, in create
    obj.save(force_insert=True, using=self.db)
  File "/Users/yxngac/Desktop/Wale_sites/.venv/lib/python3.12/site-packages/django/db/models/base.py", line 902, in save
    self.save_base(
  File "/Users/yxngac/Desktop/Wale_sites/.venv/lib/python3.12/site-packages/django/db/models/base.py", line 1008, in save_base
    updated = self._save_table(
              ^^^^^^^^^^^^^^^^^
  File "/Users/yxngac/Desktop/Wale_sites/.venv/lib/python3.12/site-packages/django/db/models/base.py", line 1169, in _save_table
    results = self._do_insert(
              ^^^^^^^^^^^^^^^^
  File "/Users/yxngac/Desktop/Wale_sites/.venv/lib/python3.12/site-packages/django/db/models/base.py", line 1210, in _do_insert
    return manager._insert(
           ^^^^^^^^^^^^^^^^
  File "/Users/yxngac/Desktop/Wale_sites/.venv/lib/python3.12/site-packages/django/db/models/manager.py", line 87, in manager_method
    return getattr(self.get_queryset(), name)(*args, **kwargs)
           ^^^^^^^^^^^^^^^^^^^^^^^^^^^^^^^^^^^^^^^^^^^^^^^^^^^
  File "/Users/yxngac/Desktop/Wale_sites/.venv/lib/python3.12/site-packages/django/db/models/query.py", line 1868, in _insert
    return query.get_compiler(using=using).execute_sql(returning_fields)
           ^^^^^^^^^^^^^^^^^^^^^^^^^^^^^^^^^^^^^^^^^^^^^^^^^^^^^^^^^^^^^
  File "/Users/yxngac/Desktop/Wale_sites/.venv/lib/python3.12/site-packages/django/db/models/sql/compiler.py", line 1882, in execute_sql
    cursor.execute(sql, params)
  File "/Users/yxngac/Desktop/Wale_sites/.venv/lib/python3.12/site-packages/django/db/backends/utils.py", line 122, in execute
    return super().execute(sql, params)
           ^^^^^^^^^^^^^^^^^^^^^^^^^^^^
  File "/Users/yxngac/Desktop/Wale_sites/.venv/lib/python3.12/site-packages/django/db/backends/utils.py", line 79, in execute
    return self._execute_with_wrappers(
           ^^^^^^^^^^^^^^^^^^^^^^^^^^^^
  File "/Users/yxngac/Desktop/Wale_sites/.venv/lib/python3.12/site-packages/django/db/backends/utils.py", line 92, in _execute_with_wrappers
    return executor(sql, params, many, context)
           ^^^^^^^^^^^^^^^^^^^^^^^^^^^^^^^^^^^^
  File "/Users/yxngac/Desktop/Wale_sites/.venv/lib/python3.12/site-packages/django/db/backends/utils.py", line 100, in _execute
    with self.db.wrap_database_errors:
         ^^^^^^^^^^^^^^^^^^^^^^^^^^^^
  File "/Users/yxngac/Desktop/Wale_sites/.venv/lib/python3.12/site-packages/django/db/utils.py", line 91, in __exit__
    raise dj_exc_value.with_traceback(traceback) from exc_value
  File "/Users/yxngac/Desktop/Wale_sites/.venv/lib/python3.12/site-packages/django/db/backends/utils.py", line 105, in _execute
    return self.cursor.execute(sql, params)
           ^^^^^^^^^^^^^^^^^^^^^^^^^^^^^^^^
django.db.utils.IntegrityError: null value in column "price" of relation "pharmacy_product" violates not-null constraint
DETAIL:  Failing row contains (2, psychadelics, dyvbgclyihwredsGBVFywrdseushigfbvwrdsieyulGFVBWRDUEYGFVBLWSRUIGF..., null, null, products/Screenshot_2025-09-17_at_1_ee3Fg4l.53.35AM.png, 1, null, 2025-09-21 00:55:03.440121+00, 2025-09-21 00:55:03.440142+00).

"POST /api/products/ HTTP/1.1" 500 200366
Internal Server Error: /api/products/
Traceback (most recent call last):
  File "/Users/yxngac/Desktop/Wale_sites/.venv/lib/python3.12/site-packages/django/db/backends/utils.py", line 105, in _execute
    return self.cursor.execute(sql, params)
           ^^^^^^^^^^^^^^^^^^^^^^^^^^^^^^^^
psycopg2.errors.NotNullViolation: null value in column "price" of relation "pharmacy_product" violates not-null constraint
DETAIL:  Failing row contains (3, psychadelics, dyvbgclyihwredsGBVFywrdseushigfbvwrdsieyulGFVBWRDUEYGFVBLWSRUIGF..., null, null, products/Screenshot_2025-09-17_at_1_9TosQal.53.35AM.png, 1, null, 2025-09-21 00:55:07.557003+00, 2025-09-21 00:55:07.55703+00).


The above exception was the direct cause of the following exception:

Traceback (most recent call last):
  File "/Users/yxngac/Desktop/Wale_sites/.venv/lib/python3.12/site-packages/django/core/handlers/exception.py", line 55, in inner
    response = get_response(request)
               ^^^^^^^^^^^^^^^^^^^^^
  File "/Users/yxngac/Desktop/Wale_sites/.venv/lib/python3.12/site-packages/django/core/handlers/base.py", line 197, in _get_response
    response = wrapped_callback(request, *callback_args, **callback_kwargs)
               ^^^^^^^^^^^^^^^^^^^^^^^^^^^^^^^^^^^^^^^^^^^^^^^^^^^^^^^^^^^^
  File "/Users/yxngac/Desktop/Wale_sites/.venv/lib/python3.12/site-packages/django/views/decorators/csrf.py", line 65, in _view_wrapper
    return view_func(request, *args, **kwargs)
           ^^^^^^^^^^^^^^^^^^^^^^^^^^^^^^^^^^^
  File "/Users/yxngac/Desktop/Wale_sites/.venv/lib/python3.12/site-packages/rest_framework/viewsets.py", line 125, in view
    return self.dispatch(request, *args, **kwargs)
           ^^^^^^^^^^^^^^^^^^^^^^^^^^^^^^^^^^^^^^^
  File "/Users/yxngac/Desktop/Wale_sites/.venv/lib/python3.12/site-packages/rest_framework/views.py", line 515, in dispatch
    response = self.handle_exception(exc)
               ^^^^^^^^^^^^^^^^^^^^^^^^^^
  File "/Users/yxngac/Desktop/Wale_sites/.venv/lib/python3.12/site-packages/rest_framework/views.py", line 475, in handle_exception
    self.raise_uncaught_exception(exc)
  File "/Users/yxngac/Desktop/Wale_sites/.venv/lib/python3.12/site-packages/rest_framework/views.py", line 486, in raise_uncaught_exception
    raise exc
  File "/Users/yxngac/Desktop/Wale_sites/.venv/lib/python3.12/site-packages/rest_framework/views.py", line 512, in dispatch
    response = handler(request, *args, **kwargs)
               ^^^^^^^^^^^^^^^^^^^^^^^^^^^^^^^^^
  File "/Users/yxngac/Desktop/Wale_sites/.venv/lib/python3.12/site-packages/rest_framework/mixins.py", line 19, in create
    self.perform_create(serializer)
  File "/Users/yxngac/Desktop/Wale_sites/.venv/lib/python3.12/site-packages/rest_framework/mixins.py", line 24, in perform_create
    serializer.save()
  File "/Users/yxngac/Desktop/Wale_sites/.venv/lib/python3.12/site-packages/rest_framework/serializers.py", line 210, in save
    self.instance = self.create(validated_data)
                    ^^^^^^^^^^^^^^^^^^^^^^^^^^^
  File "/Users/yxngac/Desktop/Wale_sites/.venv/lib/python3.12/site-packages/rest_framework/serializers.py", line 991, in create
    instance = ModelClass._default_manager.create(**validated_data)
               ^^^^^^^^^^^^^^^^^^^^^^^^^^^^^^^^^^^^^^^^^^^^^^^^^^^^
  File "/Users/yxngac/Desktop/Wale_sites/.venv/lib/python3.12/site-packages/django/db/models/manager.py", line 87, in manager_method
    return getattr(self.get_queryset(), name)(*args, **kwargs)
           ^^^^^^^^^^^^^^^^^^^^^^^^^^^^^^^^^^^^^^^^^^^^^^^^^^^
  File "/Users/yxngac/Desktop/Wale_sites/.venv/lib/python3.12/site-packages/django/db/models/query.py", line 663, in create
    obj.save(force_insert=True, using=self.db)
  File "/Users/yxngac/Desktop/Wale_sites/.venv/lib/python3.12/site-packages/django/db/models/base.py", line 902, in save
    self.save_base(
  File "/Users/yxngac/Desktop/Wale_sites/.venv/lib/python3.12/site-packages/django/db/models/base.py", line 1008, in save_base
    updated = self._save_table(
              ^^^^^^^^^^^^^^^^^
  File "/Users/yxngac/Desktop/Wale_sites/.venv/lib/python3.12/site-packages/django/db/models/base.py", line 1169, in _save_table
    results = self._do_insert(
              ^^^^^^^^^^^^^^^^
  File "/Users/yxngac/Desktop/Wale_sites/.venv/lib/python3.12/site-packages/django/db/models/base.py", line 1210, in _do_insert
    return manager._insert(
           ^^^^^^^^^^^^^^^^
  File "/Users/yxngac/Desktop/Wale_sites/.venv/lib/python3.12/site-packages/django/db/models/manager.py", line 87, in manager_method
    return getattr(self.get_queryset(), name)(*args, **kwargs)
           ^^^^^^^^^^^^^^^^^^^^^^^^^^^^^^^^^^^^^^^^^^^^^^^^^^^
  File "/Users/yxngac/Desktop/Wale_sites/.venv/lib/python3.12/site-packages/django/db/models/query.py", line 1868, in _insert
    return query.get_compiler(using=using).execute_sql(returning_fields)
           ^^^^^^^^^^^^^^^^^^^^^^^^^^^^^^^^^^^^^^^^^^^^^^^^^^^^^^^^^^^^^
  File "/Users/yxngac/Desktop/Wale_sites/.venv/lib/python3.12/site-packages/django/db/models/sql/compiler.py", line 1882, in execute_sql
    cursor.execute(sql, params)
  File "/Users/yxngac/Desktop/Wale_sites/.venv/lib/python3.12/site-packages/django/db/backends/utils.py", line 122, in execute
    return super().execute(sql, params)
           ^^^^^^^^^^^^^^^^^^^^^^^^^^^^
  File "/Users/yxngac/Desktop/Wale_sites/.venv/lib/python3.12/site-packages/django/db/backends/utils.py", line 79, in execute
    return self._execute_with_wrappers(
           ^^^^^^^^^^^^^^^^^^^^^^^^^^^^
  File "/Users/yxngac/Desktop/Wale_sites/.venv/lib/python3.12/site-packages/django/db/backends/utils.py", line 92, in _execute_with_wrappers
    return executor(sql, params, many, context)
           ^^^^^^^^^^^^^^^^^^^^^^^^^^^^^^^^^^^^
  File "/Users/yxngac/Desktop/Wale_sites/.venv/lib/python3.12/site-packages/django/db/backends/utils.py", line 100, in _execute
    with self.db.wrap_database_errors:
         ^^^^^^^^^^^^^^^^^^^^^^^^^^^^
  File "/Users/yxngac/Desktop/Wale_sites/.venv/lib/python3.12/site-packages/django/db/utils.py", line 91, in __exit__
    raise dj_exc_value.with_traceback(traceback) from exc_value
  File "/Users/yxngac/Desktop/Wale_sites/.venv/lib/python3.12/site-packages/django/db/backends/utils.py", line 105, in _execute
    return self.cursor.execute(sql, params)
           ^^^^^^^^^^^^^^^^^^^^^^^^^^^^^^^^
django.db.utils.IntegrityError: null value in column "price" of relation "pharmacy_product" violates not-null constraint
DETAIL:  Failing row contains (3, psychadelics, dyvbgclyihwredsGBVFywrdseushigfbvwrdsieyulGFVBWRDUEYGFVBLWSRUIGF..., null, null, products/Screenshot_2025-09-17_at_1_9TosQal.53.35AM.png, 1, null, 2025-09-21 00:55:07.557003+00, 2025-09-21 00:55:07.55703+00).

"POST /api/products/ HTTP/1.1" 500 200356
Internal Server Error: /api/products/
Traceback (most recent call last):
  File "/Users/yxngac/Desktop/Wale_sites/.venv/lib/python3.12/site-packages/django/db/backends/utils.py", line 105, in _execute
    return self.cursor.execute(sql, params)
           ^^^^^^^^^^^^^^^^^^^^^^^^^^^^^^^^
psycopg2.errors.NotNullViolation: null value in column "price" of relation "pharmacy_product" violates not-null constraint
DETAIL:  Failing row contains (4, psychadelics, wefregtjhtyjyujrtrtyjgdfgg55yrtgdsfdsgthtrhtr, null, null, products/Screenshot_2025-09-17_at_1_Pv0n173.53.35AM.png, 1, null, 2025-09-21 01:16:30.02996+00, 2025-09-21 01:16:30.029974+00).


The above exception was the direct cause of the following exception:

Traceback (most recent call last):
  File "/Users/yxngac/Desktop/Wale_sites/.venv/lib/python3.12/site-packages/django/core/handlers/exception.py", line 55, in inner
    response = get_response(request)
               ^^^^^^^^^^^^^^^^^^^^^
  File "/Users/yxngac/Desktop/Wale_sites/.venv/lib/python3.12/site-packages/django/core/handlers/base.py", line 197, in _get_response
    response = wrapped_callback(request, *callback_args, **callback_kwargs)
               ^^^^^^^^^^^^^^^^^^^^^^^^^^^^^^^^^^^^^^^^^^^^^^^^^^^^^^^^^^^^
  File "/Users/yxngac/Desktop/Wale_sites/.venv/lib/python3.12/site-packages/django/views/decorators/csrf.py", line 65, in _view_wrapper
    return view_func(request, *args, **kwargs)
           ^^^^^^^^^^^^^^^^^^^^^^^^^^^^^^^^^^^
  File "/Users/yxngac/Desktop/Wale_sites/.venv/lib/python3.12/site-packages/rest_framework/viewsets.py", line 125, in view
    return self.dispatch(request, *args, **kwargs)
           ^^^^^^^^^^^^^^^^^^^^^^^^^^^^^^^^^^^^^^^
  File "/Users/yxngac/Desktop/Wale_sites/.venv/lib/python3.12/site-packages/rest_framework/views.py", line 515, in dispatch
    response = self.handle_exception(exc)
               ^^^^^^^^^^^^^^^^^^^^^^^^^^
  File "/Users/yxngac/Desktop/Wale_sites/.venv/lib/python3.12/site-packages/rest_framework/views.py", line 475, in handle_exception
    self.raise_uncaught_exception(exc)
  File "/Users/yxngac/Desktop/Wale_sites/.venv/lib/python3.12/site-packages/rest_framework/views.py", line 486, in raise_uncaught_exception
    raise exc
  File "/Users/yxngac/Desktop/Wale_sites/.venv/lib/python3.12/site-packages/rest_framework/views.py", line 512, in dispatch
    response = handler(request, *args, **kwargs)
               ^^^^^^^^^^^^^^^^^^^^^^^^^^^^^^^^^
  File "/Users/yxngac/Desktop/Wale_sites/Backend/pharmacy_backend/pharmacy/views.py", line 38, in create
    self.perform_create(serializer)
  File "/Users/yxngac/Desktop/Wale_sites/.venv/lib/python3.12/site-packages/rest_framework/mixins.py", line 24, in perform_create
    serializer.save()
  File "/Users/yxngac/Desktop/Wale_sites/.venv/lib/python3.12/site-packages/rest_framework/serializers.py", line 210, in save
    self.instance = self.create(validated_data)
                    ^^^^^^^^^^^^^^^^^^^^^^^^^^^
  File "/Users/yxngac/Desktop/Wale_sites/.venv/lib/python3.12/site-packages/rest_framework/serializers.py", line 991, in create
    instance = ModelClass._default_manager.create(**validated_data)
               ^^^^^^^^^^^^^^^^^^^^^^^^^^^^^^^^^^^^^^^^^^^^^^^^^^^^
  File "/Users/yxngac/Desktop/Wale_sites/.venv/lib/python3.12/site-packages/django/db/models/manager.py", line 87, in manager_method
    return getattr(self.get_queryset(), name)(*args, **kwargs)
           ^^^^^^^^^^^^^^^^^^^^^^^^^^^^^^^^^^^^^^^^^^^^^^^^^^^
  File "/Users/yxngac/Desktop/Wale_sites/.venv/lib/python3.12/site-packages/django/db/models/query.py", line 663, in create
    obj.save(force_insert=True, using=self.db)
  File "/Users/yxngac/Desktop/Wale_sites/.venv/lib/python3.12/site-packages/django/db/models/base.py", line 902, in save
    self.save_base(
  File "/Users/yxngac/Desktop/Wale_sites/.venv/lib/python3.12/site-packages/django/db/models/base.py", line 1008, in save_base
    updated = self._save_table(
              ^^^^^^^^^^^^^^^^^
  File "/Users/yxngac/Desktop/Wale_sites/.venv/lib/python3.12/site-packages/django/db/models/base.py", line 1169, in _save_table
    results = self._do_insert(
              ^^^^^^^^^^^^^^^^
  File "/Users/yxngac/Desktop/Wale_sites/.venv/lib/python3.12/site-packages/django/db/models/base.py", line 1210, in _do_insert
    return manager._insert(
           ^^^^^^^^^^^^^^^^
  File "/Users/yxngac/Desktop/Wale_sites/.venv/lib/python3.12/site-packages/django/db/models/manager.py", line 87, in manager_method
    return getattr(self.get_queryset(), name)(*args, **kwargs)
           ^^^^^^^^^^^^^^^^^^^^^^^^^^^^^^^^^^^^^^^^^^^^^^^^^^^
  File "/Users/yxngac/Desktop/Wale_sites/.venv/lib/python3.12/site-packages/django/db/models/query.py", line 1868, in _insert
    return query.get_compiler(using=using).execute_sql(returning_fields)
           ^^^^^^^^^^^^^^^^^^^^^^^^^^^^^^^^^^^^^^^^^^^^^^^^^^^^^^^^^^^^^
  File "/Users/yxngac/Desktop/Wale_sites/.venv/lib/python3.12/site-packages/django/db/models/sql/compiler.py", line 1882, in execute_sql
    cursor.execute(sql, params)
  File "/Users/yxngac/Desktop/Wale_sites/.venv/lib/python3.12/site-packages/django/db/backends/utils.py", line 122, in execute
    return super().execute(sql, params)
           ^^^^^^^^^^^^^^^^^^^^^^^^^^^^
  File "/Users/yxngac/Desktop/Wale_sites/.venv/lib/python3.12/site-packages/django/db/backends/utils.py", line 79, in execute
    return self._execute_with_wrappers(
           ^^^^^^^^^^^^^^^^^^^^^^^^^^^^
  File "/Users/yxngac/Desktop/Wale_sites/.venv/lib/python3.12/site-packages/django/db/backends/utils.py", line 92, in _execute_with_wrappers
    return executor(sql, params, many, context)
           ^^^^^^^^^^^^^^^^^^^^^^^^^^^^^^^^^^^^
  File "/Users/yxngac/Desktop/Wale_sites/.venv/lib/python3.12/site-packages/django/db/backends/utils.py", line 100, in _execute
    with self.db.wrap_database_errors:
         ^^^^^^^^^^^^^^^^^^^^^^^^^^^^
  File "/Users/yxngac/Desktop/Wale_sites/.venv/lib/python3.12/site-packages/django/db/utils.py", line 91, in __exit__
    raise dj_exc_value.with_traceback(traceback) from exc_value
  File "/Users/yxngac/Desktop/Wale_sites/.venv/lib/python3.12/site-packages/django/db/backends/utils.py", line 105, in _execute
    return self.cursor.execute(sql, params)
           ^^^^^^^^^^^^^^^^^^^^^^^^^^^^^^^^
django.db.utils.IntegrityError: null value in column "price" of relation "pharmacy_product" violates not-null constraint
DETAIL:  Failing row contains (4, psychadelics, wefregtjhtyjyujrtrtyjgdfgg55yrtgdsfdsgthtrhtr, null, null, products/Screenshot_2025-09-17_at_1_Pv0n173.53.35AM.png, 1, null, 2025-09-21 01:16:30.02996+00, 2025-09-21 01:16:30.029974+00).

"POST /api/products/ HTTP/1.1" 500 198748
Internal Server Error: /api/products/
Traceback (most recent call last):
  File "/Users/yxngac/Desktop/Wale_sites/.venv/lib/python3.12/site-packages/django/db/backends/utils.py", line 105, in _execute
    return self.cursor.execute(sql, params)
           ^^^^^^^^^^^^^^^^^^^^^^^^^^^^^^^^
psycopg2.errors.NotNullViolation: null value in column "price" of relation "pharmacy_product" violates not-null constraint
DETAIL:  Failing row contains (5, psychadelics, wefregtjhtyjyujrtrtyjgdfgg55yrtgdsfdsgthtrhtr, null, null, products/Screenshot_2025-09-17_at_1_tGThetR.53.35AM.png, 1, null, 2025-09-21 01:17:10.769025+00, 2025-09-21 01:17:10.769039+00).


The above exception was the direct cause of the following exception:

Traceback (most recent call last):
  File "/Users/yxngac/Desktop/Wale_sites/.venv/lib/python3.12/site-packages/django/core/handlers/exception.py", line 55, in inner
    response = get_response(request)
               ^^^^^^^^^^^^^^^^^^^^^
  File "/Users/yxngac/Desktop/Wale_sites/.venv/lib/python3.12/site-packages/django/core/handlers/base.py", line 197, in _get_response
    response = wrapped_callback(request, *callback_args, **callback_kwargs)
               ^^^^^^^^^^^^^^^^^^^^^^^^^^^^^^^^^^^^^^^^^^^^^^^^^^^^^^^^^^^^
  File "/Users/yxngac/Desktop/Wale_sites/.venv/lib/python3.12/site-packages/django/views/decorators/csrf.py", line 65, in _view_wrapper
    return view_func(request, *args, **kwargs)
           ^^^^^^^^^^^^^^^^^^^^^^^^^^^^^^^^^^^
  File "/Users/yxngac/Desktop/Wale_sites/.venv/lib/python3.12/site-packages/rest_framework/viewsets.py", line 125, in view
    return self.dispatch(request, *args, **kwargs)
           ^^^^^^^^^^^^^^^^^^^^^^^^^^^^^^^^^^^^^^^
  File "/Users/yxngac/Desktop/Wale_sites/.venv/lib/python3.12/site-packages/rest_framework/views.py", line 515, in dispatch
    response = self.handle_exception(exc)
               ^^^^^^^^^^^^^^^^^^^^^^^^^^
  File "/Users/yxngac/Desktop/Wale_sites/.venv/lib/python3.12/site-packages/rest_framework/views.py", line 475, in handle_exception
    self.raise_uncaught_exception(exc)
  File "/Users/yxngac/Desktop/Wale_sites/.venv/lib/python3.12/site-packages/rest_framework/views.py", line 486, in raise_uncaught_exception
    raise exc
  File "/Users/yxngac/Desktop/Wale_sites/.venv/lib/python3.12/site-packages/rest_framework/views.py", line 512, in dispatch
    response = handler(request, *args, **kwargs)
               ^^^^^^^^^^^^^^^^^^^^^^^^^^^^^^^^^
  File "/Users/yxngac/Desktop/Wale_sites/Backend/pharmacy_backend/pharmacy/views.py", line 38, in create
    self.perform_create(serializer)
  File "/Users/yxngac/Desktop/Wale_sites/.venv/lib/python3.12/site-packages/rest_framework/mixins.py", line 24, in perform_create
    serializer.save()
  File "/Users/yxngac/Desktop/Wale_sites/.venv/lib/python3.12/site-packages/rest_framework/serializers.py", line 210, in save
    self.instance = self.create(validated_data)
                    ^^^^^^^^^^^^^^^^^^^^^^^^^^^
  File "/Users/yxngac/Desktop/Wale_sites/.venv/lib/python3.12/site-packages/rest_framework/serializers.py", line 991, in create
    instance = ModelClass._default_manager.create(**validated_data)
               ^^^^^^^^^^^^^^^^^^^^^^^^^^^^^^^^^^^^^^^^^^^^^^^^^^^^
  File "/Users/yxngac/Desktop/Wale_sites/.venv/lib/python3.12/site-packages/django/db/models/manager.py", line 87, in manager_method
    return getattr(self.get_queryset(), name)(*args, **kwargs)
           ^^^^^^^^^^^^^^^^^^^^^^^^^^^^^^^^^^^^^^^^^^^^^^^^^^^
  File "/Users/yxngac/Desktop/Wale_sites/.venv/lib/python3.12/site-packages/django/db/models/query.py", line 663, in create
    obj.save(force_insert=True, using=self.db)
  File "/Users/yxngac/Desktop/Wale_sites/.venv/lib/python3.12/site-packages/django/db/models/base.py", line 902, in save
    self.save_base(
  File "/Users/yxngac/Desktop/Wale_sites/.venv/lib/python3.12/site-packages/django/db/models/base.py", line 1008, in save_base
    updated = self._save_table(
              ^^^^^^^^^^^^^^^^^
  File "/Users/yxngac/Desktop/Wale_sites/.venv/lib/python3.12/site-packages/django/db/models/base.py", line 1169, in _save_table
    results = self._do_insert(
              ^^^^^^^^^^^^^^^^
  File "/Users/yxngac/Desktop/Wale_sites/.venv/lib/python3.12/site-packages/django/db/models/base.py", line 1210, in _do_insert
    return manager._insert(
           ^^^^^^^^^^^^^^^^
  File "/Users/yxngac/Desktop/Wale_sites/.venv/lib/python3.12/site-packages/django/db/models/manager.py", line 87, in manager_method
    return getattr(self.get_queryset(), name)(*args, **kwargs)
           ^^^^^^^^^^^^^^^^^^^^^^^^^^^^^^^^^^^^^^^^^^^^^^^^^^^
  File "/Users/yxngac/Desktop/Wale_sites/.venv/lib/python3.12/site-packages/django/db/models/query.py", line 1868, in _insert
    return query.get_compiler(using=using).execute_sql(returning_fields)
           ^^^^^^^^^^^^^^^^^^^^^^^^^^^^^^^^^^^^^^^^^^^^^^^^^^^^^^^^^^^^^
  File "/Users/yxngac/Desktop/Wale_sites/.venv/lib/python3.12/site-packages/django/db/models/sql/compiler.py", line 1882, in execute_sql
    cursor.execute(sql, params)
  File "/Users/yxngac/Desktop/Wale_sites/.venv/lib/python3.12/site-packages/django/db/backends/utils.py", line 122, in execute
    return super().execute(sql, params)
           ^^^^^^^^^^^^^^^^^^^^^^^^^^^^
  File "/Users/yxngac/Desktop/Wale_sites/.venv/lib/python3.12/site-packages/django/db/backends/utils.py", line 79, in execute
    return self._execute_with_wrappers(
           ^^^^^^^^^^^^^^^^^^^^^^^^^^^^
  File "/Users/yxngac/Desktop/Wale_sites/.venv/lib/python3.12/site-packages/django/db/backends/utils.py", line 92, in _execute_with_wrappers
    return executor(sql, params, many, context)
           ^^^^^^^^^^^^^^^^^^^^^^^^^^^^^^^^^^^^
  File "/Users/yxngac/Desktop/Wale_sites/.venv/lib/python3.12/site-packages/django/db/backends/utils.py", line 100, in _execute
    with self.db.wrap_database_errors:
         ^^^^^^^^^^^^^^^^^^^^^^^^^^^^
  File "/Users/yxngac/Desktop/Wale_sites/.venv/lib/python3.12/site-packages/django/db/utils.py", line 91, in __exit__
    raise dj_exc_value.with_traceback(traceback) from exc_value
  File "/Users/yxngac/Desktop/Wale_sites/.venv/lib/python3.12/site-packages/django/db/backends/utils.py", line 105, in _execute
    return self.cursor.execute(sql, params)
           ^^^^^^^^^^^^^^^^^^^^^^^^^^^^^^^^
django.db.utils.IntegrityError: null value in column "price" of relation "pharmacy_product" violates not-null constraint
DETAIL:  Failing row contains (5, psychadelics, wefregtjhtyjyujrtrtyjgdfgg55yrtgdsfdsgthtrhtr, null, null, products/Screenshot_2025-09-17_at_1_tGThetR.53.35AM.png, 1, null, 2025-09-21 01:17:10.769025+00, 2025-09-21 01:17:10.769039+00).

"POST /api/products/ HTTP/1.1" 500 198258
Internal Server Error: /api/products/
Traceback (most recent call last):
  File "/Users/yxngac/Desktop/Wale_sites/.venv/lib/python3.12/site-packages/django/db/backends/utils.py", line 105, in _execute
    return self.cursor.execute(sql, params)
           ^^^^^^^^^^^^^^^^^^^^^^^^^^^^^^^^
psycopg2.errors.NotNullViolation: null value in column "price" of relation "pharmacy_product" violates not-null constraint
DETAIL:  Failing row contains (6, edcf, WEGFRFGEARDTHGRTHTYGRJTYJT, null, null, products/Screenshot_2025-09-16_at_1_UgBvirz.02.35PM.png, 1, null, 2025-09-21 01:18:12.700189+00, 2025-09-21 01:18:12.700212+00).


The above exception was the direct cause of the following exception:

Traceback (most recent call last):
  File "/Users/yxngac/Desktop/Wale_sites/.venv/lib/python3.12/site-packages/django/core/handlers/exception.py", line 55, in inner
    response = get_response(request)
               ^^^^^^^^^^^^^^^^^^^^^
  File "/Users/yxngac/Desktop/Wale_sites/.venv/lib/python3.12/site-packages/django/core/handlers/base.py", line 197, in _get_response
    response = wrapped_callback(request, *callback_args, **callback_kwargs)
               ^^^^^^^^^^^^^^^^^^^^^^^^^^^^^^^^^^^^^^^^^^^^^^^^^^^^^^^^^^^^
  File "/Users/yxngac/Desktop/Wale_sites/.venv/lib/python3.12/site-packages/django/views/decorators/csrf.py", line 65, in _view_wrapper
    return view_func(request, *args, **kwargs)
           ^^^^^^^^^^^^^^^^^^^^^^^^^^^^^^^^^^^
  File "/Users/yxngac/Desktop/Wale_sites/.venv/lib/python3.12/site-packages/rest_framework/viewsets.py", line 125, in view
    return self.dispatch(request, *args, **kwargs)
           ^^^^^^^^^^^^^^^^^^^^^^^^^^^^^^^^^^^^^^^
  File "/Users/yxngac/Desktop/Wale_sites/.venv/lib/python3.12/site-packages/rest_framework/views.py", line 515, in dispatch
    response = self.handle_exception(exc)
               ^^^^^^^^^^^^^^^^^^^^^^^^^^
  File "/Users/yxngac/Desktop/Wale_sites/.venv/lib/python3.12/site-packages/rest_framework/views.py", line 475, in handle_exception
    self.raise_uncaught_exception(exc)
  File "/Users/yxngac/Desktop/Wale_sites/.venv/lib/python3.12/site-packages/rest_framework/views.py", line 486, in raise_uncaught_exception
    raise exc
  File "/Users/yxngac/Desktop/Wale_sites/.venv/lib/python3.12/site-packages/rest_framework/views.py", line 512, in dispatch
    response = handler(request, *args, **kwargs)
               ^^^^^^^^^^^^^^^^^^^^^^^^^^^^^^^^^
  File "/Users/yxngac/Desktop/Wale_sites/Backend/pharmacy_backend/pharmacy/views.py", line 38, in create
    self.perform_create(serializer)
  File "/Users/yxngac/Desktop/Wale_sites/.venv/lib/python3.12/site-packages/rest_framework/mixins.py", line 24, in perform_create
    serializer.save()
  File "/Users/yxngac/Desktop/Wale_sites/.venv/lib/python3.12/site-packages/rest_framework/serializers.py", line 210, in save
    self.instance = self.create(validated_data)
                    ^^^^^^^^^^^^^^^^^^^^^^^^^^^
  File "/Users/yxngac/Desktop/Wale_sites/.venv/lib/python3.12/site-packages/rest_framework/serializers.py", line 991, in create
    instance = ModelClass._default_manager.create(**validated_data)
               ^^^^^^^^^^^^^^^^^^^^^^^^^^^^^^^^^^^^^^^^^^^^^^^^^^^^
  File "/Users/yxngac/Desktop/Wale_sites/.venv/lib/python3.12/site-packages/django/db/models/manager.py", line 87, in manager_method
    return getattr(self.get_queryset(), name)(*args, **kwargs)
           ^^^^^^^^^^^^^^^^^^^^^^^^^^^^^^^^^^^^^^^^^^^^^^^^^^^
  File "/Users/yxngac/Desktop/Wale_sites/.venv/lib/python3.12/site-packages/django/db/models/query.py", line 663, in create
    obj.save(force_insert=True, using=self.db)
  File "/Users/yxngac/Desktop/Wale_sites/.venv/lib/python3.12/site-packages/django/db/models/base.py", line 902, in save
    self.save_base(
  File "/Users/yxngac/Desktop/Wale_sites/.venv/lib/python3.12/site-packages/django/db/models/base.py", line 1008, in save_base
    updated = self._save_table(
              ^^^^^^^^^^^^^^^^^
  File "/Users/yxngac/Desktop/Wale_sites/.venv/lib/python3.12/site-packages/django/db/models/base.py", line 1169, in _save_table
    results = self._do_insert(
              ^^^^^^^^^^^^^^^^
  File "/Users/yxngac/Desktop/Wale_sites/.venv/lib/python3.12/site-packages/django/db/models/base.py", line 1210, in _do_insert
    return manager._insert(
           ^^^^^^^^^^^^^^^^
  File "/Users/yxngac/Desktop/Wale_sites/.venv/lib/python3.12/site-packages/django/db/models/manager.py", line 87, in manager_method
    return getattr(self.get_queryset(), name)(*args, **kwargs)
           ^^^^^^^^^^^^^^^^^^^^^^^^^^^^^^^^^^^^^^^^^^^^^^^^^^^
  File "/Users/yxngac/Desktop/Wale_sites/.venv/lib/python3.12/site-packages/django/db/models/query.py", line 1868, in _insert
    return query.get_compiler(using=using).execute_sql(returning_fields)
           ^^^^^^^^^^^^^^^^^^^^^^^^^^^^^^^^^^^^^^^^^^^^^^^^^^^^^^^^^^^^^
  File "/Users/yxngac/Desktop/Wale_sites/.venv/lib/python3.12/site-packages/django/db/models/sql/compiler.py", line 1882, in execute_sql
    cursor.execute(sql, params)
  File "/Users/yxngac/Desktop/Wale_sites/.venv/lib/python3.12/site-packages/django/db/backends/utils.py", line 122, in execute
    return super().execute(sql, params)
           ^^^^^^^^^^^^^^^^^^^^^^^^^^^^
  File "/Users/yxngac/Desktop/Wale_sites/.venv/lib/python3.12/site-packages/django/db/backends/utils.py", line 79, in execute
    return self._execute_with_wrappers(
           ^^^^^^^^^^^^^^^^^^^^^^^^^^^^
  File "/Users/yxngac/Desktop/Wale_sites/.venv/lib/python3.12/site-packages/django/db/backends/utils.py", line 92, in _execute_with_wrappers
    return executor(sql, params, many, context)
           ^^^^^^^^^^^^^^^^^^^^^^^^^^^^^^^^^^^^
  File "/Users/yxngac/Desktop/Wale_sites/.venv/lib/python3.12/site-packages/django/db/backends/utils.py", line 100, in _execute
    with self.db.wrap_database_errors:
         ^^^^^^^^^^^^^^^^^^^^^^^^^^^^
  File "/Users/yxngac/Desktop/Wale_sites/.venv/lib/python3.12/site-packages/django/db/utils.py", line 91, in __exit__
    raise dj_exc_value.with_traceback(traceback) from exc_value
  File "/Users/yxngac/Desktop/Wale_sites/.venv/lib/python3.12/site-packages/django/db/backends/utils.py", line 105, in _execute
    return self.cursor.execute(sql, params)
           ^^^^^^^^^^^^^^^^^^^^^^^^^^^^^^^^
django.db.utils.IntegrityError: null value in column "price" of relation "pharmacy_product" violates not-null constraint
DETAIL:  Failing row contains (6, edcf, WEGFRFGEARDTHGRTHTYGRJTYJT, null, null, products/Screenshot_2025-09-16_at_1_UgBvirz.02.35PM.png, 1, null, 2025-09-21 01:18:12.700189+00, 2025-09-21 01:18:12.700212+00).

"POST /api/products/ HTTP/1.1" 500 197499
Internal Server Error: /api/products/
Traceback (most recent call last):
  File "/Users/yxngac/Desktop/Wale_sites/.venv/lib/python3.12/site-packages/django/db/backends/utils.py", line 105, in _execute
    return self.cursor.execute(sql, params)
           ^^^^^^^^^^^^^^^^^^^^^^^^^^^^^^^^
psycopg2.errors.NotNullViolation: null value in column "price" of relation "pharmacy_product" violates not-null constraint
DETAIL:  Failing row contains (1, psychadelics, qwferhrtyjtykjyutjgfhrjyter, null, null, products/Screenshot_2025-09-17_at_1_T46Ipig.53.35AM.png, 1, null, 2025-09-21 01:27:49.533627+00, 2025-09-21 01:27:49.533643+00).


The above exception was the direct cause of the following exception:

Traceback (most recent call last):
  File "/Users/yxngac/Desktop/Wale_sites/.venv/lib/python3.12/site-packages/django/core/handlers/exception.py", line 55, in inner
    response = get_response(request)
               ^^^^^^^^^^^^^^^^^^^^^
  File "/Users/yxngac/Desktop/Wale_sites/.venv/lib/python3.12/site-packages/django/core/handlers/base.py", line 197, in _get_response
    response = wrapped_callback(request, *callback_args, **callback_kwargs)
               ^^^^^^^^^^^^^^^^^^^^^^^^^^^^^^^^^^^^^^^^^^^^^^^^^^^^^^^^^^^^
  File "/Users/yxngac/Desktop/Wale_sites/.venv/lib/python3.12/site-packages/django/views/decorators/csrf.py", line 65, in _view_wrapper
    return view_func(request, *args, **kwargs)
           ^^^^^^^^^^^^^^^^^^^^^^^^^^^^^^^^^^^
  File "/Users/yxngac/Desktop/Wale_sites/.venv/lib/python3.12/site-packages/rest_framework/viewsets.py", line 125, in view
    return self.dispatch(request, *args, **kwargs)
           ^^^^^^^^^^^^^^^^^^^^^^^^^^^^^^^^^^^^^^^
  File "/Users/yxngac/Desktop/Wale_sites/.venv/lib/python3.12/site-packages/rest_framework/views.py", line 515, in dispatch
    response = self.handle_exception(exc)
               ^^^^^^^^^^^^^^^^^^^^^^^^^^
  File "/Users/yxngac/Desktop/Wale_sites/.venv/lib/python3.12/site-packages/rest_framework/views.py", line 475, in handle_exception
    self.raise_uncaught_exception(exc)
  File "/Users/yxngac/Desktop/Wale_sites/.venv/lib/python3.12/site-packages/rest_framework/views.py", line 486, in raise_uncaught_exception
    raise exc
  File "/Users/yxngac/Desktop/Wale_sites/.venv/lib/python3.12/site-packages/rest_framework/views.py", line 512, in dispatch
    response = handler(request, *args, **kwargs)
               ^^^^^^^^^^^^^^^^^^^^^^^^^^^^^^^^^
  File "/Users/yxngac/Desktop/Wale_sites/Backend/pharmacy_backend/pharmacy/views.py", line 39, in create
    self.perform_create(serializer)
  File "/Users/yxngac/Desktop/Wale_sites/.venv/lib/python3.12/site-packages/rest_framework/mixins.py", line 24, in perform_create
    serializer.save()
  File "/Users/yxngac/Desktop/Wale_sites/.venv/lib/python3.12/site-packages/rest_framework/serializers.py", line 210, in save
    self.instance = self.create(validated_data)
                    ^^^^^^^^^^^^^^^^^^^^^^^^^^^
  File "/Users/yxngac/Desktop/Wale_sites/.venv/lib/python3.12/site-packages/rest_framework/serializers.py", line 991, in create
    instance = ModelClass._default_manager.create(**validated_data)
               ^^^^^^^^^^^^^^^^^^^^^^^^^^^^^^^^^^^^^^^^^^^^^^^^^^^^
  File "/Users/yxngac/Desktop/Wale_sites/.venv/lib/python3.12/site-packages/django/db/models/manager.py", line 87, in manager_method
    return getattr(self.get_queryset(), name)(*args, **kwargs)
           ^^^^^^^^^^^^^^^^^^^^^^^^^^^^^^^^^^^^^^^^^^^^^^^^^^^
  File "/Users/yxngac/Desktop/Wale_sites/.venv/lib/python3.12/site-packages/django/db/models/query.py", line 663, in create
    obj.save(force_insert=True, using=self.db)
  File "/Users/yxngac/Desktop/Wale_sites/.venv/lib/python3.12/site-packages/django/db/models/base.py", line 902, in save
    self.save_base(
  File "/Users/yxngac/Desktop/Wale_sites/.venv/lib/python3.12/site-packages/django/db/models/base.py", line 1008, in save_base
    updated = self._save_table(
              ^^^^^^^^^^^^^^^^^
  File "/Users/yxngac/Desktop/Wale_sites/.venv/lib/python3.12/site-packages/django/db/models/base.py", line 1169, in _save_table
    results = self._do_insert(
              ^^^^^^^^^^^^^^^^
  File "/Users/yxngac/Desktop/Wale_sites/.venv/lib/python3.12/site-packages/django/db/models/base.py", line 1210, in _do_insert
    return manager._insert(
           ^^^^^^^^^^^^^^^^
  File "/Users/yxngac/Desktop/Wale_sites/.venv/lib/python3.12/site-packages/django/db/models/manager.py", line 87, in manager_method
    return getattr(self.get_queryset(), name)(*args, **kwargs)
           ^^^^^^^^^^^^^^^^^^^^^^^^^^^^^^^^^^^^^^^^^^^^^^^^^^^
  File "/Users/yxngac/Desktop/Wale_sites/.venv/lib/python3.12/site-packages/django/db/models/query.py", line 1868, in _insert
    return query.get_compiler(using=using).execute_sql(returning_fields)
           ^^^^^^^^^^^^^^^^^^^^^^^^^^^^^^^^^^^^^^^^^^^^^^^^^^^^^^^^^^^^^
  File "/Users/yxngac/Desktop/Wale_sites/.venv/lib/python3.12/site-packages/django/db/models/sql/compiler.py", line 1882, in execute_sql
    cursor.execute(sql, params)
  File "/Users/yxngac/Desktop/Wale_sites/.venv/lib/python3.12/site-packages/django/db/backends/utils.py", line 122, in execute
    return super().execute(sql, params)
           ^^^^^^^^^^^^^^^^^^^^^^^^^^^^
  File "/Users/yxngac/Desktop/Wale_sites/.venv/lib/python3.12/site-packages/django/db/backends/utils.py", line 79, in execute
    return self._execute_with_wrappers(
           ^^^^^^^^^^^^^^^^^^^^^^^^^^^^
  File "/Users/yxngac/Desktop/Wale_sites/.venv/lib/python3.12/site-packages/django/db/backends/utils.py", line 92, in _execute_with_wrappers
    return executor(sql, params, many, context)
           ^^^^^^^^^^^^^^^^^^^^^^^^^^^^^^^^^^^^
  File "/Users/yxngac/Desktop/Wale_sites/.venv/lib/python3.12/site-packages/django/db/backends/utils.py", line 100, in _execute
    with self.db.wrap_database_errors:
         ^^^^^^^^^^^^^^^^^^^^^^^^^^^^
  File "/Users/yxngac/Desktop/Wale_sites/.venv/lib/python3.12/site-packages/django/db/utils.py", line 91, in __exit__
    raise dj_exc_value.with_traceback(traceback) from exc_value
  File "/Users/yxngac/Desktop/Wale_sites/.venv/lib/python3.12/site-packages/django/db/backends/utils.py", line 105, in _execute
    return self.cursor.execute(sql, params)
           ^^^^^^^^^^^^^^^^^^^^^^^^^^^^^^^^
django.db.utils.IntegrityError: null value in column "price" of relation "pharmacy_product" violates not-null constraint
DETAIL:  Failing row contains (1, psychadelics, qwferhrtyjtykjyutjgfhrjyter, null, null, products/Screenshot_2025-09-17_at_1_T46Ipig.53.35AM.png, 1, null, 2025-09-21 01:27:49.533627+00, 2025-09-21 01:27:49.533643+00).

"POST /api/products/ HTTP/1.1" 500 198304
Internal Server Error: /api/products/
Traceback (most recent call last):
  File "/Users/yxngac/Desktop/Wale_sites/.venv/lib/python3.12/site-packages/django/db/backends/utils.py", line 105, in _execute
    return self.cursor.execute(sql, params)
           ^^^^^^^^^^^^^^^^^^^^^^^^^^^^^^^^
psycopg2.errors.UndefinedTable: relation "pharmacy_productvariant" does not exist
LINE 1: ..."."price", "pharmacy_productvariant"."stock" FROM "pharmacy_...
                                                             ^


The above exception was the direct cause of the following exception:

Traceback (most recent call last):
  File "/Users/yxngac/Desktop/Wale_sites/.venv/lib/python3.12/site-packages/django/core/handlers/exception.py", line 55, in inner
    response = get_response(request)
               ^^^^^^^^^^^^^^^^^^^^^
  File "/Users/yxngac/Desktop/Wale_sites/.venv/lib/python3.12/site-packages/django/core/handlers/base.py", line 197, in _get_response
    response = wrapped_callback(request, *callback_args, **callback_kwargs)
               ^^^^^^^^^^^^^^^^^^^^^^^^^^^^^^^^^^^^^^^^^^^^^^^^^^^^^^^^^^^^
  File "/Users/yxngac/Desktop/Wale_sites/.venv/lib/python3.12/site-packages/django/views/decorators/csrf.py", line 65, in _view_wrapper
    return view_func(request, *args, **kwargs)
           ^^^^^^^^^^^^^^^^^^^^^^^^^^^^^^^^^^^
  File "/Users/yxngac/Desktop/Wale_sites/.venv/lib/python3.12/site-packages/rest_framework/viewsets.py", line 125, in view
    return self.dispatch(request, *args, **kwargs)
           ^^^^^^^^^^^^^^^^^^^^^^^^^^^^^^^^^^^^^^^
  File "/Users/yxngac/Desktop/Wale_sites/.venv/lib/python3.12/site-packages/rest_framework/views.py", line 515, in dispatch
    response = self.handle_exception(exc)
               ^^^^^^^^^^^^^^^^^^^^^^^^^^
  File "/Users/yxngac/Desktop/Wale_sites/.venv/lib/python3.12/site-packages/rest_framework/views.py", line 475, in handle_exception
    self.raise_uncaught_exception(exc)
  File "/Users/yxngac/Desktop/Wale_sites/.venv/lib/python3.12/site-packages/rest_framework/views.py", line 486, in raise_uncaught_exception
    raise exc
  File "/Users/yxngac/Desktop/Wale_sites/.venv/lib/python3.12/site-packages/rest_framework/views.py", line 512, in dispatch
    response = handler(request, *args, **kwargs)
               ^^^^^^^^^^^^^^^^^^^^^^^^^^^^^^^^^
  File "/Users/yxngac/Desktop/Wale_sites/Backend/pharmacy_backend/pharmacy/views.py", line 40, in create
    headers = self.get_success_headers(serializer.data)
                                       ^^^^^^^^^^^^^^^
  File "/Users/yxngac/Desktop/Wale_sites/.venv/lib/python3.12/site-packages/rest_framework/serializers.py", line 573, in data
    ret = super().data
          ^^^^^^^^^^^^
  File "/Users/yxngac/Desktop/Wale_sites/.venv/lib/python3.12/site-packages/rest_framework/serializers.py", line 251, in data
    self._data = self.to_representation(self.instance)
                 ^^^^^^^^^^^^^^^^^^^^^^^^^^^^^^^^^^^^^
  File "/Users/yxngac/Desktop/Wale_sites/.venv/lib/python3.12/site-packages/rest_framework/serializers.py", line 540, in to_representation
    ret[field.field_name] = field.to_representation(attribute)
                            ^^^^^^^^^^^^^^^^^^^^^^^^^^^^^^^^^^
  File "/Users/yxngac/Desktop/Wale_sites/.venv/lib/python3.12/site-packages/rest_framework/serializers.py", line 716, in to_representation
    self.child.to_representation(item) for item in iterable
                                                   ^^^^^^^^
  File "/Users/yxngac/Desktop/Wale_sites/.venv/lib/python3.12/site-packages/django/db/models/query.py", line 384, in __iter__
    self._fetch_all()
  File "/Users/yxngac/Desktop/Wale_sites/.venv/lib/python3.12/site-packages/django/db/models/query.py", line 1949, in _fetch_all
    self._result_cache = list(self._iterable_class(self))
                         ^^^^^^^^^^^^^^^^^^^^^^^^^^^^^^^^
  File "/Users/yxngac/Desktop/Wale_sites/.venv/lib/python3.12/site-packages/django/db/models/query.py", line 91, in __iter__
    results = compiler.execute_sql(
              ^^^^^^^^^^^^^^^^^^^^^
  File "/Users/yxngac/Desktop/Wale_sites/.venv/lib/python3.12/site-packages/django/db/models/sql/compiler.py", line 1623, in execute_sql
    cursor.execute(sql, params)
  File "/Users/yxngac/Desktop/Wale_sites/.venv/lib/python3.12/site-packages/django/db/backends/utils.py", line 122, in execute
    return super().execute(sql, params)
           ^^^^^^^^^^^^^^^^^^^^^^^^^^^^
  File "/Users/yxngac/Desktop/Wale_sites/.venv/lib/python3.12/site-packages/django/db/backends/utils.py", line 79, in execute
    return self._execute_with_wrappers(
           ^^^^^^^^^^^^^^^^^^^^^^^^^^^^
  File "/Users/yxngac/Desktop/Wale_sites/.venv/lib/python3.12/site-packages/django/db/backends/utils.py", line 92, in _execute_with_wrappers
    return executor(sql, params, many, context)
           ^^^^^^^^^^^^^^^^^^^^^^^^^^^^^^^^^^^^
  File "/Users/yxngac/Desktop/Wale_sites/.venv/lib/python3.12/site-packages/django/db/backends/utils.py", line 100, in _execute
    with self.db.wrap_database_errors:
         ^^^^^^^^^^^^^^^^^^^^^^^^^^^^
  File "/Users/yxngac/Desktop/Wale_sites/.venv/lib/python3.12/site-packages/django/db/utils.py", line 91, in __exit__
    raise dj_exc_value.with_traceback(traceback) from exc_value
  File "/Users/yxngac/Desktop/Wale_sites/.venv/lib/python3.12/site-packages/django/db/backends/utils.py", line 105, in _execute
    return self.cursor.execute(sql, params)
           ^^^^^^^^^^^^^^^^^^^^^^^^^^^^^^^^
django.db.utils.ProgrammingError: relation "pharmacy_productvariant" does not exist
LINE 1: ..."."price", "pharmacy_productvariant"."stock" FROM "pharmacy_...
                                                             ^

"POST /api/products/ HTTP/1.1" 500 170039
Internal Server Error: /api/products/52/
Traceback (most recent call last):
  File "/Users/yxngac/Desktop/Wale_sites/.venv/lib/python3.12/site-packages/django/db/backends/utils.py", line 105, in _execute
    return self.cursor.execute(sql, params)
           ^^^^^^^^^^^^^^^^^^^^^^^^^^^^^^^^
psycopg2.errors.UndefinedColumn: column pharmacy_orderitem.variant_id does not exist
LINE 1: DELETE FROM "pharmacy_orderitem" WHERE "pharmacy_orderitem"....
                                               ^


The above exception was the direct cause of the following exception:

Traceback (most recent call last):
  File "/Users/yxngac/Desktop/Wale_sites/.venv/lib/python3.12/site-packages/django/core/handlers/exception.py", line 55, in inner
    response = get_response(request)
               ^^^^^^^^^^^^^^^^^^^^^
  File "/Users/yxngac/Desktop/Wale_sites/.venv/lib/python3.12/site-packages/django/core/handlers/base.py", line 197, in _get_response
    response = wrapped_callback(request, *callback_args, **callback_kwargs)
               ^^^^^^^^^^^^^^^^^^^^^^^^^^^^^^^^^^^^^^^^^^^^^^^^^^^^^^^^^^^^
  File "/Users/yxngac/Desktop/Wale_sites/.venv/lib/python3.12/site-packages/django/views/decorators/csrf.py", line 65, in _view_wrapper
    return view_func(request, *args, **kwargs)
           ^^^^^^^^^^^^^^^^^^^^^^^^^^^^^^^^^^^
  File "/Users/yxngac/Desktop/Wale_sites/.venv/lib/python3.12/site-packages/rest_framework/viewsets.py", line 125, in view
    return self.dispatch(request, *args, **kwargs)
           ^^^^^^^^^^^^^^^^^^^^^^^^^^^^^^^^^^^^^^^
  File "/Users/yxngac/Desktop/Wale_sites/.venv/lib/python3.12/site-packages/rest_framework/views.py", line 515, in dispatch
    response = self.handle_exception(exc)
               ^^^^^^^^^^^^^^^^^^^^^^^^^^
  File "/Users/yxngac/Desktop/Wale_sites/.venv/lib/python3.12/site-packages/rest_framework/views.py", line 475, in handle_exception
    self.raise_uncaught_exception(exc)
  File "/Users/yxngac/Desktop/Wale_sites/.venv/lib/python3.12/site-packages/rest_framework/views.py", line 486, in raise_uncaught_exception
    raise exc
  File "/Users/yxngac/Desktop/Wale_sites/.venv/lib/python3.12/site-packages/rest_framework/views.py", line 512, in dispatch
    response = handler(request, *args, **kwargs)
               ^^^^^^^^^^^^^^^^^^^^^^^^^^^^^^^^^
  File "/Users/yxngac/Desktop/Wale_sites/.venv/lib/python3.12/site-packages/rest_framework/mixins.py", line 91, in destroy
    self.perform_destroy(instance)
  File "/Users/yxngac/Desktop/Wale_sites/.venv/lib/python3.12/site-packages/rest_framework/mixins.py", line 95, in perform_destroy
    instance.delete()
  File "/Users/yxngac/Desktop/Wale_sites/.venv/lib/python3.12/site-packages/django/db/models/base.py", line 1281, in delete
    return collector.delete()
           ^^^^^^^^^^^^^^^^^^
  File "/Users/yxngac/Desktop/Wale_sites/.venv/lib/python3.12/site-packages/django/db/models/deletion.py", line 467, in delete
    count = qs._raw_delete(using=self.using)
            ^^^^^^^^^^^^^^^^^^^^^^^^^^^^^^^^
  File "/Users/yxngac/Desktop/Wale_sites/.venv/lib/python3.12/site-packages/django/db/models/query.py", line 1221, in _raw_delete
    return query.get_compiler(using).execute_sql(ROW_COUNT)
           ^^^^^^^^^^^^^^^^^^^^^^^^^^^^^^^^^^^^^^^^^^^^^^^^
  File "/Users/yxngac/Desktop/Wale_sites/.venv/lib/python3.12/site-packages/django/db/models/sql/compiler.py", line 1623, in execute_sql
    cursor.execute(sql, params)
  File "/Users/yxngac/Desktop/Wale_sites/.venv/lib/python3.12/site-packages/django/db/backends/utils.py", line 122, in execute
    return super().execute(sql, params)
           ^^^^^^^^^^^^^^^^^^^^^^^^^^^^
  File "/Users/yxngac/Desktop/Wale_sites/.venv/lib/python3.12/site-packages/django/db/backends/utils.py", line 79, in execute
    return self._execute_with_wrappers(
           ^^^^^^^^^^^^^^^^^^^^^^^^^^^^
  File "/Users/yxngac/Desktop/Wale_sites/.venv/lib/python3.12/site-packages/django/db/backends/utils.py", line 92, in _execute_with_wrappers
    return executor(sql, params, many, context)
           ^^^^^^^^^^^^^^^^^^^^^^^^^^^^^^^^^^^^
  File "/Users/yxngac/Desktop/Wale_sites/.venv/lib/python3.12/site-packages/django/db/backends/utils.py", line 100, in _execute
    with self.db.wrap_database_errors:
         ^^^^^^^^^^^^^^^^^^^^^^^^^^^^
  File "/Users/yxngac/Desktop/Wale_sites/.venv/lib/python3.12/site-packages/django/db/utils.py", line 91, in __exit__
    raise dj_exc_value.with_traceback(traceback) from exc_value
  File "/Users/yxngac/Desktop/Wale_sites/.venv/lib/python3.12/site-packages/django/db/backends/utils.py", line 105, in _execute
    return self.cursor.execute(sql, params)
           ^^^^^^^^^^^^^^^^^^^^^^^^^^^^^^^^
django.db.utils.ProgrammingError: column pharmacy_orderitem.variant_id does not exist
LINE 1: DELETE FROM "pharmacy_orderitem" WHERE "pharmacy_orderitem"....
                                               ^

"DELETE /api/products/52/ HTTP/1.1" 500 147594
Internal Server Error: /api/products/49/
Traceback (most recent call last):
  File "/Users/yxngac/Desktop/Wale_sites/.venv/lib/python3.12/site-packages/django/db/backends/utils.py", line 105, in _execute
    return self.cursor.execute(sql, params)
           ^^^^^^^^^^^^^^^^^^^^^^^^^^^^^^^^
psycopg2.errors.UndefinedColumn: column pharmacy_orderitem.variant_id does not exist
LINE 1: DELETE FROM "pharmacy_orderitem" WHERE "pharmacy_orderitem"....
                                               ^


The above exception was the direct cause of the following exception:

Traceback (most recent call last):
  File "/Users/yxngac/Desktop/Wale_sites/.venv/lib/python3.12/site-packages/django/core/handlers/exception.py", line 55, in inner
    response = get_response(request)
               ^^^^^^^^^^^^^^^^^^^^^
  File "/Users/yxngac/Desktop/Wale_sites/.venv/lib/python3.12/site-packages/django/core/handlers/base.py", line 197, in _get_response
    response = wrapped_callback(request, *callback_args, **callback_kwargs)
               ^^^^^^^^^^^^^^^^^^^^^^^^^^^^^^^^^^^^^^^^^^^^^^^^^^^^^^^^^^^^
  File "/Users/yxngac/Desktop/Wale_sites/.venv/lib/python3.12/site-packages/django/views/decorators/csrf.py", line 65, in _view_wrapper
    return view_func(request, *args, **kwargs)
           ^^^^^^^^^^^^^^^^^^^^^^^^^^^^^^^^^^^
  File "/Users/yxngac/Desktop/Wale_sites/.venv/lib/python3.12/site-packages/rest_framework/viewsets.py", line 125, in view
    return self.dispatch(request, *args, **kwargs)
           ^^^^^^^^^^^^^^^^^^^^^^^^^^^^^^^^^^^^^^^
  File "/Users/yxngac/Desktop/Wale_sites/.venv/lib/python3.12/site-packages/rest_framework/views.py", line 515, in dispatch
    response = self.handle_exception(exc)
               ^^^^^^^^^^^^^^^^^^^^^^^^^^
  File "/Users/yxngac/Desktop/Wale_sites/.venv/lib/python3.12/site-packages/rest_framework/views.py", line 475, in handle_exception
    self.raise_uncaught_exception(exc)
  File "/Users/yxngac/Desktop/Wale_sites/.venv/lib/python3.12/site-packages/rest_framework/views.py", line 486, in raise_uncaught_exception
    raise exc
  File "/Users/yxngac/Desktop/Wale_sites/.venv/lib/python3.12/site-packages/rest_framework/views.py", line 512, in dispatch
    response = handler(request, *args, **kwargs)
               ^^^^^^^^^^^^^^^^^^^^^^^^^^^^^^^^^
  File "/Users/yxngac/Desktop/Wale_sites/.venv/lib/python3.12/site-packages/rest_framework/mixins.py", line 91, in destroy
    self.perform_destroy(instance)
  File "/Users/yxngac/Desktop/Wale_sites/.venv/lib/python3.12/site-packages/rest_framework/mixins.py", line 95, in perform_destroy
    instance.delete()
  File "/Users/yxngac/Desktop/Wale_sites/.venv/lib/python3.12/site-packages/django/db/models/base.py", line 1281, in delete
    return collector.delete()
           ^^^^^^^^^^^^^^^^^^
  File "/Users/yxngac/Desktop/Wale_sites/.venv/lib/python3.12/site-packages/django/db/models/deletion.py", line 467, in delete
    count = qs._raw_delete(using=self.using)
            ^^^^^^^^^^^^^^^^^^^^^^^^^^^^^^^^
  File "/Users/yxngac/Desktop/Wale_sites/.venv/lib/python3.12/site-packages/django/db/models/query.py", line 1221, in _raw_delete
    return query.get_compiler(using).execute_sql(ROW_COUNT)
           ^^^^^^^^^^^^^^^^^^^^^^^^^^^^^^^^^^^^^^^^^^^^^^^^
  File "/Users/yxngac/Desktop/Wale_sites/.venv/lib/python3.12/site-packages/django/db/models/sql/compiler.py", line 1623, in execute_sql
    cursor.execute(sql, params)
  File "/Users/yxngac/Desktop/Wale_sites/.venv/lib/python3.12/site-packages/django/db/backends/utils.py", line 122, in execute
    return super().execute(sql, params)
           ^^^^^^^^^^^^^^^^^^^^^^^^^^^^
  File "/Users/yxngac/Desktop/Wale_sites/.venv/lib/python3.12/site-packages/django/db/backends/utils.py", line 79, in execute
    return self._execute_with_wrappers(
           ^^^^^^^^^^^^^^^^^^^^^^^^^^^^
  File "/Users/yxngac/Desktop/Wale_sites/.venv/lib/python3.12/site-packages/django/db/backends/utils.py", line 92, in _execute_with_wrappers
    return executor(sql, params, many, context)
           ^^^^^^^^^^^^^^^^^^^^^^^^^^^^^^^^^^^^
  File "/Users/yxngac/Desktop/Wale_sites/.venv/lib/python3.12/site-packages/django/db/backends/utils.py", line 100, in _execute
    with self.db.wrap_database_errors:
         ^^^^^^^^^^^^^^^^^^^^^^^^^^^^
  File "/Users/yxngac/Desktop/Wale_sites/.venv/lib/python3.12/site-packages/django/db/utils.py", line 91, in __exit__
    raise dj_exc_value.with_traceback(traceback) from exc_value
  File "/Users/yxngac/Desktop/Wale_sites/.venv/lib/python3.12/site-packages/django/db/backends/utils.py", line 105, in _execute
    return self.cursor.execute(sql, params)
           ^^^^^^^^^^^^^^^^^^^^^^^^^^^^^^^^
django.db.utils.ProgrammingError: column pharmacy_orderitem.variant_id does not exist
LINE 1: DELETE FROM "pharmacy_orderitem" WHERE "pharmacy_orderitem"....
                                               ^

"DELETE /api/products/49/ HTTP/1.1" 500 147594
Internal Server Error: /api/products/49/
Traceback (most recent call last):
  File "/Users/yxngac/Desktop/Wale_sites/.venv/lib/python3.12/site-packages/django/db/backends/utils.py", line 105, in _execute
    return self.cursor.execute(sql, params)
           ^^^^^^^^^^^^^^^^^^^^^^^^^^^^^^^^
psycopg2.errors.UndefinedColumn: column pharmacy_orderitem.variant_id does not exist
LINE 1: DELETE FROM "pharmacy_orderitem" WHERE "pharmacy_orderitem"....
                                               ^


The above exception was the direct cause of the following exception:

Traceback (most recent call last):
  File "/Users/yxngac/Desktop/Wale_sites/.venv/lib/python3.12/site-packages/django/core/handlers/exception.py", line 55, in inner
    response = get_response(request)
               ^^^^^^^^^^^^^^^^^^^^^
  File "/Users/yxngac/Desktop/Wale_sites/.venv/lib/python3.12/site-packages/django/core/handlers/base.py", line 197, in _get_response
    response = wrapped_callback(request, *callback_args, **callback_kwargs)
               ^^^^^^^^^^^^^^^^^^^^^^^^^^^^^^^^^^^^^^^^^^^^^^^^^^^^^^^^^^^^
  File "/Users/yxngac/Desktop/Wale_sites/.venv/lib/python3.12/site-packages/django/views/decorators/csrf.py", line 65, in _view_wrapper
    return view_func(request, *args, **kwargs)
           ^^^^^^^^^^^^^^^^^^^^^^^^^^^^^^^^^^^
  File "/Users/yxngac/Desktop/Wale_sites/.venv/lib/python3.12/site-packages/rest_framework/viewsets.py", line 125, in view
    return self.dispatch(request, *args, **kwargs)
           ^^^^^^^^^^^^^^^^^^^^^^^^^^^^^^^^^^^^^^^
  File "/Users/yxngac/Desktop/Wale_sites/.venv/lib/python3.12/site-packages/rest_framework/views.py", line 515, in dispatch
    response = self.handle_exception(exc)
               ^^^^^^^^^^^^^^^^^^^^^^^^^^
  File "/Users/yxngac/Desktop/Wale_sites/.venv/lib/python3.12/site-packages/rest_framework/views.py", line 475, in handle_exception
    self.raise_uncaught_exception(exc)
  File "/Users/yxngac/Desktop/Wale_sites/.venv/lib/python3.12/site-packages/rest_framework/views.py", line 486, in raise_uncaught_exception
    raise exc
  File "/Users/yxngac/Desktop/Wale_sites/.venv/lib/python3.12/site-packages/rest_framework/views.py", line 512, in dispatch
    response = handler(request, *args, **kwargs)
               ^^^^^^^^^^^^^^^^^^^^^^^^^^^^^^^^^
  File "/Users/yxngac/Desktop/Wale_sites/.venv/lib/python3.12/site-packages/rest_framework/mixins.py", line 91, in destroy
    self.perform_destroy(instance)
  File "/Users/yxngac/Desktop/Wale_sites/.venv/lib/python3.12/site-packages/rest_framework/mixins.py", line 95, in perform_destroy
    instance.delete()
  File "/Users/yxngac/Desktop/Wale_sites/.venv/lib/python3.12/site-packages/django/db/models/base.py", line 1281, in delete
    return collector.delete()
           ^^^^^^^^^^^^^^^^^^
  File "/Users/yxngac/Desktop/Wale_sites/.venv/lib/python3.12/site-packages/django/db/models/deletion.py", line 467, in delete
    count = qs._raw_delete(using=self.using)
            ^^^^^^^^^^^^^^^^^^^^^^^^^^^^^^^^
  File "/Users/yxngac/Desktop/Wale_sites/.venv/lib/python3.12/site-packages/django/db/models/query.py", line 1221, in _raw_delete
    return query.get_compiler(using).execute_sql(ROW_COUNT)
           ^^^^^^^^^^^^^^^^^^^^^^^^^^^^^^^^^^^^^^^^^^^^^^^^
  File "/Users/yxngac/Desktop/Wale_sites/.venv/lib/python3.12/site-packages/django/db/models/sql/compiler.py", line 1623, in execute_sql
    cursor.execute(sql, params)
  File "/Users/yxngac/Desktop/Wale_sites/.venv/lib/python3.12/site-packages/django/db/backends/utils.py", line 122, in execute
    return super().execute(sql, params)
           ^^^^^^^^^^^^^^^^^^^^^^^^^^^^
  File "/Users/yxngac/Desktop/Wale_sites/.venv/lib/python3.12/site-packages/django/db/backends/utils.py", line 79, in execute
    return self._execute_with_wrappers(
           ^^^^^^^^^^^^^^^^^^^^^^^^^^^^
  File "/Users/yxngac/Desktop/Wale_sites/.venv/lib/python3.12/site-packages/django/db/backends/utils.py", line 92, in _execute_with_wrappers
    return executor(sql, params, many, context)
           ^^^^^^^^^^^^^^^^^^^^^^^^^^^^^^^^^^^^
  File "/Users/yxngac/Desktop/Wale_sites/.venv/lib/python3.12/site-packages/django/db/backends/utils.py", line 100, in _execute
    with self.db.wrap_database_errors:
         ^^^^^^^^^^^^^^^^^^^^^^^^^^^^
  File "/Users/yxngac/Desktop/Wale_sites/.venv/lib/python3.12/site-packages/django/db/utils.py", line 91, in __exit__
    raise dj_exc_value.with_traceback(traceback) from exc_value
  File "/Users/yxngac/Desktop/Wale_sites/.venv/lib/python3.12/site-packages/django/db/backends/utils.py", line 105, in _execute
    return self.cursor.execute(sql, params)
           ^^^^^^^^^^^^^^^^^^^^^^^^^^^^^^^^
django.db.utils.ProgrammingError: column pharmacy_orderitem.variant_id does not exist
LINE 1: DELETE FROM "pharmacy_orderitem" WHERE "pharmacy_orderitem"....
                                               ^

"DELETE /api/products/49/ HTTP/1.1" 500 147594
Internal Server Error: /api/products/49/
Traceback (most recent call last):
  File "/Users/yxngac/Desktop/Wale_sites/.venv/lib/python3.12/site-packages/django/db/backends/utils.py", line 105, in _execute
    return self.cursor.execute(sql, params)
           ^^^^^^^^^^^^^^^^^^^^^^^^^^^^^^^^
psycopg2.errors.UndefinedColumn: column pharmacy_orderitem.variant_id does not exist
LINE 1: DELETE FROM "pharmacy_orderitem" WHERE "pharmacy_orderitem"....
                                               ^


The above exception was the direct cause of the following exception:

Traceback (most recent call last):
  File "/Users/yxngac/Desktop/Wale_sites/.venv/lib/python3.12/site-packages/django/core/handlers/exception.py", line 55, in inner
    response = get_response(request)
               ^^^^^^^^^^^^^^^^^^^^^
  File "/Users/yxngac/Desktop/Wale_sites/.venv/lib/python3.12/site-packages/django/core/handlers/base.py", line 197, in _get_response
    response = wrapped_callback(request, *callback_args, **callback_kwargs)
               ^^^^^^^^^^^^^^^^^^^^^^^^^^^^^^^^^^^^^^^^^^^^^^^^^^^^^^^^^^^^
  File "/Users/yxngac/Desktop/Wale_sites/.venv/lib/python3.12/site-packages/django/views/decorators/csrf.py", line 65, in _view_wrapper
    return view_func(request, *args, **kwargs)
           ^^^^^^^^^^^^^^^^^^^^^^^^^^^^^^^^^^^
  File "/Users/yxngac/Desktop/Wale_sites/.venv/lib/python3.12/site-packages/rest_framework/viewsets.py", line 125, in view
    return self.dispatch(request, *args, **kwargs)
           ^^^^^^^^^^^^^^^^^^^^^^^^^^^^^^^^^^^^^^^
  File "/Users/yxngac/Desktop/Wale_sites/.venv/lib/python3.12/site-packages/rest_framework/views.py", line 515, in dispatch
    response = self.handle_exception(exc)
               ^^^^^^^^^^^^^^^^^^^^^^^^^^
  File "/Users/yxngac/Desktop/Wale_sites/.venv/lib/python3.12/site-packages/rest_framework/views.py", line 475, in handle_exception
    self.raise_uncaught_exception(exc)
  File "/Users/yxngac/Desktop/Wale_sites/.venv/lib/python3.12/site-packages/rest_framework/views.py", line 486, in raise_uncaught_exception
    raise exc
  File "/Users/yxngac/Desktop/Wale_sites/.venv/lib/python3.12/site-packages/rest_framework/views.py", line 512, in dispatch
    response = handler(request, *args, **kwargs)
               ^^^^^^^^^^^^^^^^^^^^^^^^^^^^^^^^^
  File "/Users/yxngac/Desktop/Wale_sites/.venv/lib/python3.12/site-packages/rest_framework/mixins.py", line 91, in destroy
    self.perform_destroy(instance)
  File "/Users/yxngac/Desktop/Wale_sites/.venv/lib/python3.12/site-packages/rest_framework/mixins.py", line 95, in perform_destroy
    instance.delete()
  File "/Users/yxngac/Desktop/Wale_sites/.venv/lib/python3.12/site-packages/django/db/models/base.py", line 1281, in delete
    return collector.delete()
           ^^^^^^^^^^^^^^^^^^
  File "/Users/yxngac/Desktop/Wale_sites/.venv/lib/python3.12/site-packages/django/db/models/deletion.py", line 467, in delete
    count = qs._raw_delete(using=self.using)
            ^^^^^^^^^^^^^^^^^^^^^^^^^^^^^^^^
  File "/Users/yxngac/Desktop/Wale_sites/.venv/lib/python3.12/site-packages/django/db/models/query.py", line 1221, in _raw_delete
    return query.get_compiler(using).execute_sql(ROW_COUNT)
           ^^^^^^^^^^^^^^^^^^^^^^^^^^^^^^^^^^^^^^^^^^^^^^^^
  File "/Users/yxngac/Desktop/Wale_sites/.venv/lib/python3.12/site-packages/django/db/models/sql/compiler.py", line 1623, in execute_sql
    cursor.execute(sql, params)
  File "/Users/yxngac/Desktop/Wale_sites/.venv/lib/python3.12/site-packages/django/db/backends/utils.py", line 122, in execute
    return super().execute(sql, params)
           ^^^^^^^^^^^^^^^^^^^^^^^^^^^^
  File "/Users/yxngac/Desktop/Wale_sites/.venv/lib/python3.12/site-packages/django/db/backends/utils.py", line 79, in execute
    return self._execute_with_wrappers(
           ^^^^^^^^^^^^^^^^^^^^^^^^^^^^
  File "/Users/yxngac/Desktop/Wale_sites/.venv/lib/python3.12/site-packages/django/db/backends/utils.py", line 92, in _execute_with_wrappers
    return executor(sql, params, many, context)
           ^^^^^^^^^^^^^^^^^^^^^^^^^^^^^^^^^^^^
  File "/Users/yxngac/Desktop/Wale_sites/.venv/lib/python3.12/site-packages/django/db/backends/utils.py", line 100, in _execute
    with self.db.wrap_database_errors:
         ^^^^^^^^^^^^^^^^^^^^^^^^^^^^
  File "/Users/yxngac/Desktop/Wale_sites/.venv/lib/python3.12/site-packages/django/db/utils.py", line 91, in __exit__
    raise dj_exc_value.with_traceback(traceback) from exc_value
  File "/Users/yxngac/Desktop/Wale_sites/.venv/lib/python3.12/site-packages/django/db/backends/utils.py", line 105, in _execute
    return self.cursor.execute(sql, params)
           ^^^^^^^^^^^^^^^^^^^^^^^^^^^^^^^^
django.db.utils.ProgrammingError: column pharmacy_orderitem.variant_id does not exist
LINE 1: DELETE FROM "pharmacy_orderitem" WHERE "pharmacy_orderitem"....
                                               ^

"DELETE /api/products/49/ HTTP/1.1" 500 147594
Internal Server Error: /api/products/5/
Traceback (most recent call last):
  File "/Users/yxngac/Desktop/Wale_sites/.venv/lib/python3.12/site-packages/django/db/backends/utils.py", line 105, in _execute
    return self.cursor.execute(sql, params)
           ^^^^^^^^^^^^^^^^^^^^^^^^^^^^^^^^
psycopg2.errors.UndefinedColumn: column pharmacy_orderitem.variant_id does not exist
LINE 1: DELETE FROM "pharmacy_orderitem" WHERE "pharmacy_orderitem"....
                                               ^


The above exception was the direct cause of the following exception:

Traceback (most recent call last):
  File "/Users/yxngac/Desktop/Wale_sites/.venv/lib/python3.12/site-packages/django/core/handlers/exception.py", line 55, in inner
    response = get_response(request)
               ^^^^^^^^^^^^^^^^^^^^^
  File "/Users/yxngac/Desktop/Wale_sites/.venv/lib/python3.12/site-packages/django/core/handlers/base.py", line 197, in _get_response
    response = wrapped_callback(request, *callback_args, **callback_kwargs)
               ^^^^^^^^^^^^^^^^^^^^^^^^^^^^^^^^^^^^^^^^^^^^^^^^^^^^^^^^^^^^
  File "/Users/yxngac/Desktop/Wale_sites/.venv/lib/python3.12/site-packages/django/views/decorators/csrf.py", line 65, in _view_wrapper
    return view_func(request, *args, **kwargs)
           ^^^^^^^^^^^^^^^^^^^^^^^^^^^^^^^^^^^
  File "/Users/yxngac/Desktop/Wale_sites/.venv/lib/python3.12/site-packages/rest_framework/viewsets.py", line 125, in view
    return self.dispatch(request, *args, **kwargs)
           ^^^^^^^^^^^^^^^^^^^^^^^^^^^^^^^^^^^^^^^
  File "/Users/yxngac/Desktop/Wale_sites/.venv/lib/python3.12/site-packages/rest_framework/views.py", line 515, in dispatch
    response = self.handle_exception(exc)
               ^^^^^^^^^^^^^^^^^^^^^^^^^^
  File "/Users/yxngac/Desktop/Wale_sites/.venv/lib/python3.12/site-packages/rest_framework/views.py", line 475, in handle_exception
    self.raise_uncaught_exception(exc)
  File "/Users/yxngac/Desktop/Wale_sites/.venv/lib/python3.12/site-packages/rest_framework/views.py", line 486, in raise_uncaught_exception
    raise exc
  File "/Users/yxngac/Desktop/Wale_sites/.venv/lib/python3.12/site-packages/rest_framework/views.py", line 512, in dispatch
    response = handler(request, *args, **kwargs)
               ^^^^^^^^^^^^^^^^^^^^^^^^^^^^^^^^^
  File "/Users/yxngac/Desktop/Wale_sites/.venv/lib/python3.12/site-packages/rest_framework/mixins.py", line 91, in destroy
    self.perform_destroy(instance)
  File "/Users/yxngac/Desktop/Wale_sites/.venv/lib/python3.12/site-packages/rest_framework/mixins.py", line 95, in perform_destroy
    instance.delete()
  File "/Users/yxngac/Desktop/Wale_sites/.venv/lib/python3.12/site-packages/django/db/models/base.py", line 1281, in delete
    return collector.delete()
           ^^^^^^^^^^^^^^^^^^
  File "/Users/yxngac/Desktop/Wale_sites/.venv/lib/python3.12/site-packages/django/db/models/deletion.py", line 467, in delete
    count = qs._raw_delete(using=self.using)
            ^^^^^^^^^^^^^^^^^^^^^^^^^^^^^^^^
  File "/Users/yxngac/Desktop/Wale_sites/.venv/lib/python3.12/site-packages/django/db/models/query.py", line 1221, in _raw_delete
    return query.get_compiler(using).execute_sql(ROW_COUNT)
           ^^^^^^^^^^^^^^^^^^^^^^^^^^^^^^^^^^^^^^^^^^^^^^^^
  File "/Users/yxngac/Desktop/Wale_sites/.venv/lib/python3.12/site-packages/django/db/models/sql/compiler.py", line 1623, in execute_sql
    cursor.execute(sql, params)
  File "/Users/yxngac/Desktop/Wale_sites/.venv/lib/python3.12/site-packages/django/db/backends/utils.py", line 122, in execute
    return super().execute(sql, params)
           ^^^^^^^^^^^^^^^^^^^^^^^^^^^^
  File "/Users/yxngac/Desktop/Wale_sites/.venv/lib/python3.12/site-packages/django/db/backends/utils.py", line 79, in execute
    return self._execute_with_wrappers(
           ^^^^^^^^^^^^^^^^^^^^^^^^^^^^
  File "/Users/yxngac/Desktop/Wale_sites/.venv/lib/python3.12/site-packages/django/db/backends/utils.py", line 92, in _execute_with_wrappers
    return executor(sql, params, many, context)
           ^^^^^^^^^^^^^^^^^^^^^^^^^^^^^^^^^^^^
  File "/Users/yxngac/Desktop/Wale_sites/.venv/lib/python3.12/site-packages/django/db/backends/utils.py", line 100, in _execute
    with self.db.wrap_database_errors:
         ^^^^^^^^^^^^^^^^^^^^^^^^^^^^
  File "/Users/yxngac/Desktop/Wale_sites/.venv/lib/python3.12/site-packages/django/db/utils.py", line 91, in __exit__
    raise dj_exc_value.with_traceback(traceback) from exc_value
  File "/Users/yxngac/Desktop/Wale_sites/.venv/lib/python3.12/site-packages/django/db/backends/utils.py", line 105, in _execute
    return self.cursor.execute(sql, params)
           ^^^^^^^^^^^^^^^^^^^^^^^^^^^^^^^^
django.db.utils.ProgrammingError: column pharmacy_orderitem.variant_id does not exist
LINE 1: DELETE FROM "pharmacy_orderitem" WHERE "pharmacy_orderitem"....
                                               ^

"DELETE /api/products/5/ HTTP/1.1" 500 147448
Internal Server Error: /api/products/5/
Traceback (most recent call last):
  File "/Users/yxngac/Desktop/Wale_sites/.venv/lib/python3.12/site-packages/django/db/backends/utils.py", line 105, in _execute
    return self.cursor.execute(sql, params)
           ^^^^^^^^^^^^^^^^^^^^^^^^^^^^^^^^
psycopg2.errors.UndefinedColumn: column pharmacy_orderitem.variant_id does not exist
LINE 1: DELETE FROM "pharmacy_orderitem" WHERE "pharmacy_orderitem"....
                                               ^


The above exception was the direct cause of the following exception:

Traceback (most recent call last):
  File "/Users/yxngac/Desktop/Wale_sites/.venv/lib/python3.12/site-packages/django/core/handlers/exception.py", line 55, in inner
    response = get_response(request)
               ^^^^^^^^^^^^^^^^^^^^^
  File "/Users/yxngac/Desktop/Wale_sites/.venv/lib/python3.12/site-packages/django/core/handlers/base.py", line 197, in _get_response
    response = wrapped_callback(request, *callback_args, **callback_kwargs)
               ^^^^^^^^^^^^^^^^^^^^^^^^^^^^^^^^^^^^^^^^^^^^^^^^^^^^^^^^^^^^
  File "/Users/yxngac/Desktop/Wale_sites/.venv/lib/python3.12/site-packages/django/views/decorators/csrf.py", line 65, in _view_wrapper
    return view_func(request, *args, **kwargs)
           ^^^^^^^^^^^^^^^^^^^^^^^^^^^^^^^^^^^
  File "/Users/yxngac/Desktop/Wale_sites/.venv/lib/python3.12/site-packages/rest_framework/viewsets.py", line 125, in view
    return self.dispatch(request, *args, **kwargs)
           ^^^^^^^^^^^^^^^^^^^^^^^^^^^^^^^^^^^^^^^
  File "/Users/yxngac/Desktop/Wale_sites/.venv/lib/python3.12/site-packages/rest_framework/views.py", line 515, in dispatch
    response = self.handle_exception(exc)
               ^^^^^^^^^^^^^^^^^^^^^^^^^^
  File "/Users/yxngac/Desktop/Wale_sites/.venv/lib/python3.12/site-packages/rest_framework/views.py", line 475, in handle_exception
    self.raise_uncaught_exception(exc)
  File "/Users/yxngac/Desktop/Wale_sites/.venv/lib/python3.12/site-packages/rest_framework/views.py", line 486, in raise_uncaught_exception
    raise exc
  File "/Users/yxngac/Desktop/Wale_sites/.venv/lib/python3.12/site-packages/rest_framework/views.py", line 512, in dispatch
    response = handler(request, *args, **kwargs)
               ^^^^^^^^^^^^^^^^^^^^^^^^^^^^^^^^^
  File "/Users/yxngac/Desktop/Wale_sites/.venv/lib/python3.12/site-packages/rest_framework/mixins.py", line 91, in destroy
    self.perform_destroy(instance)
  File "/Users/yxngac/Desktop/Wale_sites/.venv/lib/python3.12/site-packages/rest_framework/mixins.py", line 95, in perform_destroy
    instance.delete()
  File "/Users/yxngac/Desktop/Wale_sites/.venv/lib/python3.12/site-packages/django/db/models/base.py", line 1281, in delete
    return collector.delete()
           ^^^^^^^^^^^^^^^^^^
  File "/Users/yxngac/Desktop/Wale_sites/.venv/lib/python3.12/site-packages/django/db/models/deletion.py", line 467, in delete
    count = qs._raw_delete(using=self.using)
            ^^^^^^^^^^^^^^^^^^^^^^^^^^^^^^^^
  File "/Users/yxngac/Desktop/Wale_sites/.venv/lib/python3.12/site-packages/django/db/models/query.py", line 1221, in _raw_delete
    return query.get_compiler(using).execute_sql(ROW_COUNT)
           ^^^^^^^^^^^^^^^^^^^^^^^^^^^^^^^^^^^^^^^^^^^^^^^^
  File "/Users/yxngac/Desktop/Wale_sites/.venv/lib/python3.12/site-packages/django/db/models/sql/compiler.py", line 1623, in execute_sql
    cursor.execute(sql, params)
  File "/Users/yxngac/Desktop/Wale_sites/.venv/lib/python3.12/site-packages/django/db/backends/utils.py", line 122, in execute
    return super().execute(sql, params)
           ^^^^^^^^^^^^^^^^^^^^^^^^^^^^
  File "/Users/yxngac/Desktop/Wale_sites/.venv/lib/python3.12/site-packages/django/db/backends/utils.py", line 79, in execute
    return self._execute_with_wrappers(
           ^^^^^^^^^^^^^^^^^^^^^^^^^^^^
  File "/Users/yxngac/Desktop/Wale_sites/.venv/lib/python3.12/site-packages/django/db/backends/utils.py", line 92, in _execute_with_wrappers
    return executor(sql, params, many, context)
           ^^^^^^^^^^^^^^^^^^^^^^^^^^^^^^^^^^^^
  File "/Users/yxngac/Desktop/Wale_sites/.venv/lib/python3.12/site-packages/django/db/backends/utils.py", line 100, in _execute
    with self.db.wrap_database_errors:
         ^^^^^^^^^^^^^^^^^^^^^^^^^^^^
  File "/Users/yxngac/Desktop/Wale_sites/.venv/lib/python3.12/site-packages/django/db/utils.py", line 91, in __exit__
    raise dj_exc_value.with_traceback(traceback) from exc_value
  File "/Users/yxngac/Desktop/Wale_sites/.venv/lib/python3.12/site-packages/django/db/backends/utils.py", line 105, in _execute
    return self.cursor.execute(sql, params)
           ^^^^^^^^^^^^^^^^^^^^^^^^^^^^^^^^
django.db.utils.ProgrammingError: column pharmacy_orderitem.variant_id does not exist
LINE 1: DELETE FROM "pharmacy_orderitem" WHERE "pharmacy_orderitem"....
                                               ^

"DELETE /api/products/5/ HTTP/1.1" 500 147448
Internal Server Error: /api/products/5/
Traceback (most recent call last):
  File "/Users/yxngac/Desktop/Wale_sites/.venv/lib/python3.12/site-packages/django/db/backends/utils.py", line 105, in _execute
    return self.cursor.execute(sql, params)
           ^^^^^^^^^^^^^^^^^^^^^^^^^^^^^^^^
psycopg2.errors.UndefinedColumn: column pharmacy_orderitem.variant_id does not exist
LINE 1: DELETE FROM "pharmacy_orderitem" WHERE "pharmacy_orderitem"....
                                               ^


The above exception was the direct cause of the following exception:

Traceback (most recent call last):
  File "/Users/yxngac/Desktop/Wale_sites/.venv/lib/python3.12/site-packages/django/core/handlers/exception.py", line 55, in inner
    response = get_response(request)
               ^^^^^^^^^^^^^^^^^^^^^
  File "/Users/yxngac/Desktop/Wale_sites/.venv/lib/python3.12/site-packages/django/core/handlers/base.py", line 197, in _get_response
    response = wrapped_callback(request, *callback_args, **callback_kwargs)
               ^^^^^^^^^^^^^^^^^^^^^^^^^^^^^^^^^^^^^^^^^^^^^^^^^^^^^^^^^^^^
  File "/Users/yxngac/Desktop/Wale_sites/.venv/lib/python3.12/site-packages/django/views/decorators/csrf.py", line 65, in _view_wrapper
    return view_func(request, *args, **kwargs)
           ^^^^^^^^^^^^^^^^^^^^^^^^^^^^^^^^^^^
  File "/Users/yxngac/Desktop/Wale_sites/.venv/lib/python3.12/site-packages/rest_framework/viewsets.py", line 125, in view
    return self.dispatch(request, *args, **kwargs)
           ^^^^^^^^^^^^^^^^^^^^^^^^^^^^^^^^^^^^^^^
  File "/Users/yxngac/Desktop/Wale_sites/.venv/lib/python3.12/site-packages/rest_framework/views.py", line 515, in dispatch
    response = self.handle_exception(exc)
               ^^^^^^^^^^^^^^^^^^^^^^^^^^
  File "/Users/yxngac/Desktop/Wale_sites/.venv/lib/python3.12/site-packages/rest_framework/views.py", line 475, in handle_exception
    self.raise_uncaught_exception(exc)
  File "/Users/yxngac/Desktop/Wale_sites/.venv/lib/python3.12/site-packages/rest_framework/views.py", line 486, in raise_uncaught_exception
    raise exc
  File "/Users/yxngac/Desktop/Wale_sites/.venv/lib/python3.12/site-packages/rest_framework/views.py", line 512, in dispatch
    response = handler(request, *args, **kwargs)
               ^^^^^^^^^^^^^^^^^^^^^^^^^^^^^^^^^
  File "/Users/yxngac/Desktop/Wale_sites/.venv/lib/python3.12/site-packages/rest_framework/mixins.py", line 91, in destroy
    self.perform_destroy(instance)
  File "/Users/yxngac/Desktop/Wale_sites/.venv/lib/python3.12/site-packages/rest_framework/mixins.py", line 95, in perform_destroy
    instance.delete()
  File "/Users/yxngac/Desktop/Wale_sites/.venv/lib/python3.12/site-packages/django/db/models/base.py", line 1281, in delete
    return collector.delete()
           ^^^^^^^^^^^^^^^^^^
  File "/Users/yxngac/Desktop/Wale_sites/.venv/lib/python3.12/site-packages/django/db/models/deletion.py", line 467, in delete
    count = qs._raw_delete(using=self.using)
            ^^^^^^^^^^^^^^^^^^^^^^^^^^^^^^^^
  File "/Users/yxngac/Desktop/Wale_sites/.venv/lib/python3.12/site-packages/django/db/models/query.py", line 1221, in _raw_delete
    return query.get_compiler(using).execute_sql(ROW_COUNT)
           ^^^^^^^^^^^^^^^^^^^^^^^^^^^^^^^^^^^^^^^^^^^^^^^^
  File "/Users/yxngac/Desktop/Wale_sites/.venv/lib/python3.12/site-packages/django/db/models/sql/compiler.py", line 1623, in execute_sql
    cursor.execute(sql, params)
  File "/Users/yxngac/Desktop/Wale_sites/.venv/lib/python3.12/site-packages/django/db/backends/utils.py", line 122, in execute
    return super().execute(sql, params)
           ^^^^^^^^^^^^^^^^^^^^^^^^^^^^
  File "/Users/yxngac/Desktop/Wale_sites/.venv/lib/python3.12/site-packages/django/db/backends/utils.py", line 79, in execute
    return self._execute_with_wrappers(
           ^^^^^^^^^^^^^^^^^^^^^^^^^^^^
  File "/Users/yxngac/Desktop/Wale_sites/.venv/lib/python3.12/site-packages/django/db/backends/utils.py", line 92, in _execute_with_wrappers
    return executor(sql, params, many, context)
           ^^^^^^^^^^^^^^^^^^^^^^^^^^^^^^^^^^^^
  File "/Users/yxngac/Desktop/Wale_sites/.venv/lib/python3.12/site-packages/django/db/backends/utils.py", line 100, in _execute
    with self.db.wrap_database_errors:
         ^^^^^^^^^^^^^^^^^^^^^^^^^^^^
  File "/Users/yxngac/Desktop/Wale_sites/.venv/lib/python3.12/site-packages/django/db/utils.py", line 91, in __exit__
    raise dj_exc_value.with_traceback(traceback) from exc_value
  File "/Users/yxngac/Desktop/Wale_sites/.venv/lib/python3.12/site-packages/django/db/backends/utils.py", line 105, in _execute
    return self.cursor.execute(sql, params)
           ^^^^^^^^^^^^^^^^^^^^^^^^^^^^^^^^
django.db.utils.ProgrammingError: column pharmacy_orderitem.variant_id does not exist
LINE 1: DELETE FROM "pharmacy_orderitem" WHERE "pharmacy_orderitem"....
                                               ^

"DELETE /api/products/5/ HTTP/1.1" 500 146934
